Workbook

Sheet Equipments
A1: Id | B1: NameId | C1: _ | D1: IconIndex | E1: Rank | F1: Attribute
A2: 10 | B2: 10 | C2: =INDEX(TextData!B:B,MATCH(B2,TextData!A:A)) -> 装備なし | D2: 0 | E2: 0 | F2: 0
A3: 1010 | B3: 1010 | C3: =INDEX(TextData!B:B,MATCH(B3,TextData!A:A)) -> 炎砦の魔石 | D3: 1 | E3: 1 | F3: 1
A4: 1020 | B4: 1020 | C4: =INDEX(TextData!B:B,MATCH(B4,TextData!A:A)) -> ブラストバングル | D4: 1 | E4: 1 | F4: 1
A5: 1030 | B5: 1030 | C5: =INDEX(TextData!B:B,MATCH(B5,TextData!A:A)) -> エルドチョーカー | D5: 1 | E5: 1 | F5: 1
A6: 1040 | B6: 1040 | C6: =INDEX(TextData!B:B,MATCH(B6,TextData!A:A)) -> 火の化身のベルト | D6: 1 | E6: 1 | F6: 1
A7: 1110 | B7: 1110 | C7: =INDEX(TextData!B:B,MATCH(B7,TextData!A:A)) -> ボルグの熱石 | D7: 1 | E7: 2 | F7: 1
A8: 1120 | B8: 1120 | C8: =INDEX(TextData!B:B,MATCH(B8,TextData!A:A)) -> シンモラのピアス | D8: 1 | E8: 2 | F8: 1
A9: 1130 | B9: 1130 | C9: =INDEX(TextData!B:B,MATCH(B9,TextData!A:A)) -> スルトの指輪 | D9: 1 | E9: 2 | F9: 1
A10: 1210 | B10: 1210 | C10: =INDEX(TextData!B:B,MATCH(B10,TextData!A:A)) -> ハールバルト | D10: 1 | E10: 3 | F10: 1
A11: 1220 | B11: 1220 | C11: =INDEX(TextData!B:B,MATCH(B11,TextData!A:A)) -> ファールバウティ | D11: 1 | E11: 3 | F11: 1
A12: 1230 | B12: 1230 | C12: =INDEX(TextData!B:B,MATCH(B12,TextData!A:A)) -> グリンカムビ | D12: 1 | E12: 3 | F12: 1
A13: 1240 | B13: 1240 | C13: =INDEX(TextData!B:B,MATCH(B13,TextData!A:A)) -> レーヴァテイン | D13: 1 | E13: 3 | F13: 1
... A65: 7020 | B65: 7020 | C65: =INDEX(TextData!B:B,MATCH(B65,TextData!A:A)) -> ドヴェルグの指輪 | D65: 6 | E65: 11 | F65: 6

Sheet Learnings
A1: EquipmentId | B1: SkillId | C1: LearningRate | D1: EquipmentOnly
A2: 1010 | B2: 11010 | C2: 10 | D2: 0
A3: 1010 | B3: 501010 | C3: 10 | D3: 0
A4: 1020 | B4: 11020 | C4: 10 | D4: 0
A5: 1020 | B5: 501020 | C5: 10 | D5: 0
A6: 1030 | B6: 11030 | C6: 10 | D6: 0
A7: 1030 | B7: 501030 | C7: 10 | D7: 0
A8: 1040 | B8: 11040 | C8: 10 | D8: 0
A9: 1040 | B9: 501040 | C9: 10 | D9: 0
A10: 1110 | B10: 1020 | C10: 8 | D10: 0
A11: 1110 | B11: 501110 | C11: 8 | D11: 0
A12: 1120 | B12: 1030 | C12: 8 | D12: 0
A13: 1120 | B13: 501120 | C13: 8 | D13: 0
... A135: 7020 | B135: 507020 | C135: 0 | D135: 1

Sheet TextData
A1: Id | B1: Text | F1: EnglishText
A2: 10 | B2: 装備なし | F2: No Equipment
A3: 1010 | B3: 炎砦の魔石 | F3: Fortress Firestone
A4: 1020 | B4: ブラストバングル | F4: Blast Bangle
A5: 1030 | B5: エルドチョーカー | F5: Eld Choker
A6: 1040 | B6: 火の化身のベルト | F6: Avatar of Flame Belt
A7: 1110 | B7: ボルグの熱石 | F7: Fortress Firestone
A8: 1120 | B8: シンモラのピアス | F8: Blast Bangle
A9: 1130 | B9: スルトの指輪 | F9: Ring of Surtr
A10: 1210 | B10: ハールバルト
A11: 1220 | B11: ファールバウティ
A12: 1230 | B12: グリンカムビ
A13: 1240 | B13: レーヴァテイン
A14: 2010 | B14: 雷の結晶 | F14: Thunder Crystal
A15: 2020 | B15: トルドの雷針 | F15: Trold Thunder Pin
A16: 2030 | B16: 雷神の指輪 | F16: Thunder God Ring
A17: 2040 | B17: 電撃のタリスマン | F17: Lightning Talisman
A18: 2110 | B18: トールズリング | F18: Thunder God Ring
A19: 2120 | B19: 放電の耳飾り | F19: Lightning Talisman
A20: 2130 | B20: マグニのたすき | F20: Magni's Focus Sash
A21: 2210 | B21: ストームルーラー
A22: 2220 | B22: 雷鳴の手斧
A23: 2230 | B23: 電光石火のブーツ
A24: 2240 | B24: 光速の魔弓
A25: 3010 | B25: ブリザードアンク | F25: Blizzard Ankh
A26: 3020 | B26: 氷風の耳飾り | F26: Icy Breeze Earring
A27: 3030 | B27: スヴェルの結界 | F27: Svel's Barrier
A28: 3040 | B28: 巨人の首輪 | F28: Giant's Collar
A29: 3110 | B29: スヴェルの結界 | F29: Blizzard Ankh
A30: 3120 | B30: 氷河の涙石 | F30: Icy Breeze Earring
A31: 3130 | B31: グラースティア | F31: Glassterior
A32: 3210 | B32: グレイシャー
A33: 3220 | B33: 吹雪の弓
A34: 3230 | B34: ニヴルアヴァランチェ
A35: 3240 | B35: エルト・カタラクト
A36: 4010 | B36: アルフの光羽 | F36: Alf's Light Feather
A37: 4020 | B37: 聖光のリボン | F37: Holy Ribbon
A38: 4030 | B38: グリンの金剛毛 | F38: Grin's Vajra Hair
A39: 4040 | B39: アースブローチ | F39: Earth Brooch
A40: 4110 | B40: 妖精の羽飾り | F40: Alf's Light Feather
...
