Workbook

Sheet Skills
A1: Id | B1: NameId | C1: Name | D1: IconIndex | E1: _ | F1: AnimationId | G1: _ | H1: AnimationType | I1: _ | J1: MpCost | K1: CountTurn | L1: Rank | M1: Attribute | N1: _ | O1: SkillType | P1: _ | Q1: TargetType | R1: _ | S1: ScopeType | T1: _ | U1: Range | V1: RepeatTime | W1: AliveOnly | X1: TimingOnlyCount
A2: 0 | B2: 0 | C2: =INDEX(TextData!B:B,MATCH(B2,TextData!A:A)) -> - | D2: 0 | E2: =INDEX(Define!X:X,MATCH(D2,Define!W:W)) -> なし | F2: 0 | H2: 0 | I2: =INDEX(Define!B:B,MATCH(H2,Define!A:A)) -> なし | J2: 0 | K2: 0 | L2: 0 | M2: 0 | N2: =INDEX(Define!E:E,MATCH(M2,Define!D:D)) -> なし | O2: 0 | P2: =INDEX(Define!H:H,MATCH(O2,Define!G:G)) -> なし | Q2: 0 | R2: =INDEX(Define!K:K,MATCH(Q2,Define!J:J)) -> なし | S2: 0 | T2: =INDEX(Define!N:N,MATCH(S2,Define!M:M)) -> なし | U2: 1 | V2: 1 | W2: 1 | X2: 0
A3: 1 | B3: 1 | C3: =INDEX(TextData!B:B,MATCH(B3,TextData!A:A)) -> はずす | D3: 0 | E3: =INDEX(Define!X:X,MATCH(D3,Define!W:W)) -> なし | F3: 0 | H3: 0 | I3: =INDEX(Define!B:B,MATCH(H3,Define!A:A)) -> なし | J3: 0 | K3: 0 | L3: 0 | M3: 0 | N3: =INDEX(Define!E:E,MATCH(M3,Define!D:D)) -> なし | O3: 0 | P3: =INDEX(Define!H:H,MATCH(O3,Define!G:G)) -> なし | Q3: 0 | R3: =INDEX(Define!K:K,MATCH(Q3,Define!J:J)) -> なし | S3: 0 | T3: =INDEX(Define!N:N,MATCH(S3,Define!M:M)) -> なし | U3: 1 | V3: 1 | W3: 1 | X3: 0
A4: 2 | B4: 1 | C4: =INDEX(TextData!B:B,MATCH(B4,TextData!A:A)) -> はずす | D4: 1 | E4: =INDEX(Define!X:X,MATCH(D4,Define!W:W)) -> 元素 | F4: 0 | H4: 1 | I4: =INDEX(Define!B:B,MATCH(H4,Define!A:A)) -> 単体 | J4: 0 | K4: 0 | L4: 0 | M4: 0 | N4: =INDEX(Define!E:E,MATCH(M4,Define!D:D)) -> なし | O4: 1 | P4: =INDEX(Define!H:H,MATCH(O4,Define!G:G)) -> 魔法 | Q4: 1 | R4: =INDEX(Define!K:K,MATCH(Q4,Define!J:J)) -> 相手 | S4: 1 | T4: =INDEX(Define!N:N,MATCH(S4,Define!M:M)) -> 単体 | U4: 2 | V4: 1 | W4: 1 | X4: 0
A5: 11 | B5: 11 | C5: =INDEX(TextData!B:B,MATCH(B5,TextData!A:A)) -> 覚醒 | D5: 5 | E5: =INDEX(Define!X:X,MATCH(D5,Define!W:W)) -> 超次元 | F5: 11 | G5: =INDEX([1]Animations!B:B,MATCH(F5,[1]Animations!A:A)) -> tktk01/Magic2 | H5: 1 | I5: =INDEX(Define!B:B,MATCH(H5,Define!A:A)) -> 単体 | J5: 0 | K5: 0 | L5: 0 | M5: 0 | N5: =INDEX(Define!E:E,MATCH(M5,Define!D:D)) -> なし | O5: 3 | P5: =INDEX(Define!H:H,MATCH(O5,Define!G:G)) -> 神化 | Q5: 4 | R5: =INDEX(Define!K:K,MATCH(Q5,Define!J:J)) -> 自身 | S5: 4 | T5: =INDEX(Define!N:N,MATCH(S5,Define!M:M)) -> 自身 | U5: 1 | V5: 1 | W5: 1 | X5: 0
A6: 21 | B6: 21 | C6: =INDEX(TextData!B:B,MATCH(B6,TextData!A:A)) -> 覚醒解除 | D6: 5 | E6: =INDEX(Define!X:X,MATCH(D6,Define!W:W)) -> 超次元 | F6: 0 | H6: 1 | I6: =INDEX(Define!B:B,MATCH(H6,Define!A:A)) -> 単体 | J6: 0 | K6: 0 | L6: 0 | M6: 0 | N6: =INDEX(Define!E:E,MATCH(M6,Define!D:D)) -> なし | O6: 1 | P6: =INDEX(Define!H:H,MATCH(O6,Define!G:G)) -> 魔法 | Q6: 4 | R6: =INDEX(Define!K:K,MATCH(Q6,Define!J:J)) -> 自身 | S6: 4 | T6: =INDEX(Define!N:N,MATCH(S6,Define!M:M)) -> 自身 | U6: 1 | V6: 1 | W6: 1 | X6: 0
A7: 31 | B7: 31 | C7: =INDEX(TextData!B:B,MATCH(B7,TextData!A:A)) -> 拘束制御 | D7: 3 | E7: =INDEX(Define!X:X,MATCH(D7,Define!W:W)) -> 理術 | F7: 0 | H7: 1 | I7: =INDEX(Define!B:B,MATCH(H7,Define!A:A)) -> 単体 | J7: 0 | K7: 0 | L7: 0 | M7: 2 | N7: =INDEX(Define!E:E,MATCH(M7,Define!D:D)) -> 雷 | O7: 0 | P7: =INDEX(Define!H:H,MATCH(O7,Define!G:G)) -> なし | Q7: 1 | R7: =INDEX(Define!K:K,MATCH(Q7,Define!J:J)) -> 相手 | S7: 1 | T7: =INDEX(Define!N:N,MATCH(S7,Define!M:M)) -> 単体 | U7: 2 | V7: 1 | W7: 1 | X7: 0
A8: 32 | B8: 32 | C8: =INDEX(TextData!B:B,MATCH(B8,TextData!A:A)) -> 拘束ダメージ解除 | D8: 3 | E8: =INDEX(Define!X:X,MATCH(D8,Define!W:W)) -> 理術 | F8: 0 | H8: 1 | I8: =INDEX(Define!B:B,MATCH(H8,Define!A:A)) -> 単体 | J8: 0 | K8: 0 | L8: 0 | M8: 2 | N8: =INDEX(Define!E:E,MATCH(M8,Define!D:D)) -> 雷 | O8: 0 | P8: =INDEX(Define!H:H,MATCH(O8,Define!G:G)) -> なし | Q8: 4 | R8: =INDEX(Define!K:K,MATCH(Q8,Define!J:J)) -> 自身 | S8: 4 | T8: =INDEX(Define!N:N,MATCH(S8,Define!M:M)) -> 自身 | U8: 1 | V8: 1 | W8: 1 | X8: 0
A9: 33 | B9: 33 | C9: =INDEX(TextData!B:B,MATCH(B9,TextData!A:A)) -> 居合 | D9: 3 | E9: =INDEX(Define!X:X,MATCH(D9,Define!W:W)) -> 理術 | F9: 0 | H9: 1 | I9: =INDEX(Define!B:B,MATCH(H9,Define!A:A)) -> 単体 | J9: 0 | K9: 0 | L9: 0 | M9: 2 | N9: =INDEX(Define!E:E,MATCH(M9,Define!D:D)) -> 雷 | O9: 0 | P9: =INDEX(Define!H:H,MATCH(O9,Define!G:G)) -> なし | Q9: 1 | R9: =INDEX(Define!K:K,MATCH(Q9,Define!J:J)) -> 相手 | S9: 1 | T9: =INDEX(Define!N:N,MATCH(S9,Define!M:M)) -> 単体 | U9: 2 | V9: 1 | W9: 1 | X9: 0
A10: 1010 | B10: 1010 | C10: =INDEX(TextData!B:B,MATCH(B10,TextData!A:A)) -> ファイアボール | D10: 1 | E10: =INDEX(Define!X:X,MATCH(D10,Define!W:W)) -> 元素 | F10: 2101 | G10: =INDEX([1]Animations!B:B,MATCH(F10,[1]Animations!A:A)) -> tktk01/Fire2 | H10: 1 | I10: =INDEX(Define!B:B,MATCH(H10,Define!A:A)) -> 単体 | J10: 0 | K10: 0 | L10: 10 | M10: 1 | N10: =INDEX(Define!E:E,MATCH(M10,Define!D:D)) -> 炎 | O10: 1 | P10: =INDEX(Define!H:H,MATCH(O10,Define!G:G)) -> 魔法 | Q10: 1 | R10: =INDEX(Define!K:K,MATCH(Q10,Define!J:J)) -> 相手 | S10: 1 | T10: =INDEX(Define!N:N,MATCH(S10,Define!M:M)) -> 単体 | U10: 1 | V10: 1 | W10: 1 | X10: 0
A11: 1020 | B11: 1020 | C11: =INDEX(TextData!B:B,MATCH(B11,TextData!A:A)) -> フレイムクラッシュ | D11: 1 | E11: =INDEX(Define!X:X,MATCH(D11,Define!W:W)) -> 元素 | F11: 101 | G11: =INDEX([1]Animations!B:B,MATCH(F11,[1]Animations!A:A)) -> MakerEffect/FireOne1 | H11: 1 | I11: =INDEX(Define!B:B,MATCH(H11,Define!A:A)) -> 単体 | J11: 0 | K11: 2 | L11: 20 | M11: 1 | N11: =INDEX(Define!E:E,MATCH(M11,Define!D:D)) -> 炎 | O11: 1 | P11: =INDEX(Define!H:H,MATCH(O11,Define!G:G)) -> 魔法 | Q11: 1 | R11: =INDEX(Define!K:K,MATCH(Q11,Define!J:J)) -> 相手 | S11: 1 | T11: =INDEX(Define!N:N,MATCH(S11,Define!M:M)) -> 単体 | U11: 1 | V11: 1 | W11: 1 | X11: 0
A12: 1030 | B12: 1030 | C12: =INDEX(TextData!B:B,MATCH(B12,TextData!A:A)) -> ブレイクウォール | D12: 1 | E12: =INDEX(Define!X:X,MATCH(D12,Define!W:W)) -> 元素 | F12: 102 | G12: =INDEX([1]Animations!B:B,MATCH(F12,[1]Animations!A:A)) -> MakerEffect/FireOne2 | H12: 1 | I12: =INDEX(Define!B:B,MATCH(H12,Define!A:A)) -> 単体 | J12: 0 | K12: 2 | L12: 20 | M12: 1 | N12: =INDEX(Define!E:E,MATCH(M12,Define!D:D)) -> 炎 | O12: 1 | P12: =INDEX(Define!H:H,MATCH(O12,Define!G:G)) -> 魔法 | Q12: 1 | R12: =INDEX(Define!K:K,MATCH(Q12,Define!J:J)) -> 相手 | S12: 1 | T12: =INDEX(Define!N:N,MATCH(S12,Define!M:M)) -> 単体 | U12: 1 | V12: 1 | W12: 1 | X12: 0
A13: 1040 | B13: 1040 | C13: =INDEX(TextData!B:B,MATCH(B13,TextData!A:A)) -> フィニッシュスタブ | D13: 1 | E13: =INDEX(Define!X:X,MATCH(D13,Define!W:W)) -> 元素 | F13: 102 | G13: =INDEX([1]Animations!B:B,MATCH(F13,[1]Animations!A:A)) -> MakerEffect/FireOne2 | H13: 1 | I13: =INDEX(Define!B:B,MATCH(H13,Define!A:A)) -> 単体 | J13: 0 | K13: 2 | L13: 20 | M13: 1 | N13: =INDEX(Define!E:E,MATCH(M13,Define!D:D)) -> 炎 | O13: 1 | P13: =INDEX(Define!H:H,MATCH(O13,Define!G:G)) -> 魔法 | Q13: 1 | R13: =INDEX(Define!K:K,MATCH(Q13,Define!J:J)) -> 相手 | S13: 1 | T13: =INDEX(Define!N:N,MATCH(S13,Define!M:M)) -> 単体 | U13: 1 | V13: 1 | W13: 1 | X13: 0
A14: 1050 | B14: 1050 | C14: =INDEX(TextData!B:B,MATCH(B14,TextData!A:A)) -> フレイムレイン | D14: 1 | E14: =INDEX(Define!X:X,MATCH(D14,Define!W:W)) -> 元素 | F14: 2104 | G14: =INDEX([1]Animations!B:B,MATCH(F14,[1]Animations!A:A)) -> NA_Effekseer/NA_magic_006_c1 | H14: 1 | I14: =INDEX(Define!B:B,MATCH(H14,Define!A:A)) -> 単体 | J14: 0 | K14: 2 | L14: 20 | M14: 1 | N14: =INDEX(Define!E:E,MATCH(M14,Define!D:D)) -> 炎 | O14: 1 | P14: =INDEX(Define!H:H,MATCH(O14,Define!G:G)) -> 魔法 | Q14: 1 | R14: =INDEX(Define!K:K,MATCH(Q14,Define!J:J)) -> 相手 | S14: 1 | T14: =INDEX(Define!N:N,MATCH(S14,Define!M:M)) -> 単体 | U14: 1 | V14: 5 | W14: 1 | X14: 0
A15: 1070 | B15: 1070 | C15: =INDEX(TextData!B:B,MATCH(B15,TextData!A:A)) -> バーニングソウル | D15: 2 | E15: =INDEX(Define!X:X,MATCH(D15,Define!W:W)) -> 光 | F15: 101 | G15: =INDEX([1]Animations!B:B,MATCH(F15,[1]Animations!A:A)) -> MakerEffect/FireOne1 | H15: 1 | I15: =INDEX(Define!B:B,MATCH(H15,Define!A:A)) -> 単体 | J15: 0 | K15: 3 | L15: 20 | M15: 1 | N15: =INDEX(Define!E:E,MATCH(M15,Define!D:D)) -> 炎 | O15: 1 | P15: =INDEX(Define!H:H,MATCH(O15,Define!G:G)) -> 魔法 | Q15: 2 | R15: =INDEX(Define!K:K,MATCH(Q15,Define!J:J)) -> 味方 | S15: 1 | T15: =INDEX(Define!N:N,MATCH(S15,Define!M:M)) -> 単体 | U15: 1 | V15: 1 | W15: 1 | X15: 0
A16: 1080 | B16: 1080 | C16: =INDEX(TextData!B:B,MATCH(B16,TextData!A:A)) -> レイジングバウンサー | D16: 1 | E16: =INDEX(Define!X:X,MATCH(D16,Define!W:W)) -> 元素 | F16: 3005 | G16: =INDEX([1]Animations!B:B,MATCH(F16,[1]Animations!A:A)) -> Genfulew_Effect/B&S_MinMax_AttackUp | H16: 1 | I16: =INDEX(Define!B:B,MATCH(H16,Define!A:A)) -> 単体 | J16: 0 | K16: 2 | L16: 20 | M16: 1 | N16: =INDEX(Define!E:E,MATCH(M16,Define!D:D)) -> 炎 | O16: 1 | P16: =INDEX(Define!H:H,MATCH(O16,Define!G:G)) -> 魔法 | Q16: 4 | R16: =INDEX(Define!K:K,MATCH(Q16,Define!J:J)) -> 自身 | S16: 4 | T16: =INDEX(Define!N:N,MATCH(S16,Define!M:M)) -> 自身 | U16: 1 | V16: 1 | W16: 1 | X16: 0
A17: 1110 | B17: 1110 | C17: =INDEX(TextData!B:B,MATCH(B17,TextData!A:A)) -> バーンストーム | D17: 1 | E17: =INDEX(Define!X:X,MATCH(D17,Define!W:W)) -> 元素 | F17: 101 | G17: =INDEX([1]Animations!B:B,MATCH(F17,[1]Animations!A:A)) -> MakerEffect/FireOne1 | H17: 2 | I17: =INDEX(Define!B:B,MATCH(H17,Define!A:A)) -> 列 | J17: 0 | K17: 3 | L17: 30 | M17: 1 | N17: =INDEX(Define!E:E,MATCH(M17,Define!D:D)) -> 炎 | O17: 1 | P17: =INDEX(Define!H:H,MATCH(O17,Define!G:G)) -> 魔法 | Q17: 1 | R17: =INDEX(Define!K:K,MATCH(Q17,Define!J:J)) -> 相手 | S17: 2 | T17: =INDEX(Define!N:N,MATCH(S17,Define!M:M)) -> 列 | U17: 1 | V17: 1 | W17: 1 | X17: 0
A18: 1120 | B18: 1120 | C18: =INDEX(TextData!B:B,MATCH(B18,TextData!A:A)) -> イクスティンクション | D18: 1 | E18: =INDEX(Define!X:X,MATCH(D18,Define!W:W)) -> 元素 | F18: 102 | G18: =INDEX([1]Animations!B:B,MATCH(F18,[1]Animations!A:A)) -> MakerEffect/FireOne2 | H18: 1 | I18: =INDEX(Define!B:B,MATCH(H18,Define!A:A)) -> 単体 | J18: 0 | K18: 3 | L18: 30 | M18: 1 | N18: =INDEX(Define!E:E,MATCH(M18,Define!D:D)) -> 炎 | O18: 1 | P18: =INDEX(Define!H:H,MATCH(O18,Define!G:G)) -> 魔法 | Q18: 1 | R18: =INDEX(Define!K:K,MATCH(Q18,Define!J:J)) -> 相手 | S18: 1 | T18: =INDEX(Define!N:N,MATCH(S18,Define!M:M)) -> 単体 | U18: 1 | V18: 1 | W18: 1 | X18: 0
A19: 1930 | B19: 1930 | C19: =INDEX(TextData!B:B,MATCH(B19,TextData!A:A)) -> ヒートスタンプ | D19: 2 | E19: =INDEX(Define!X:X,MATCH(D19,Define!W:W)) -> 光 | F19: 21 | G19: =INDEX([1]Animations!B:B,MATCH(F19,[1]Animations!A:A)) -> tktk01/Magic2 | H19: 1 | I19: =INDEX(Define!B:B,MATCH(H19,Define!A:A)) -> 単体 | J19: 0 | K19: 2 | L19: 30 | M19: 1 | N19: =INDEX(Define!E:E,MATCH(M19,Define!D:D)) -> 炎 | O19: 1 | P19: =INDEX(Define!H:H,MATCH(O19,Define!G:G)) -> 魔法 | Q19: 2 | R19: =INDEX(Define!K:K,MATCH(Q19,Define!J:J)) -> 味方 | S19: 1 | T19: =INDEX(Define!N:N,MATCH(S19,Define!M:M)) -> 単体 | U19: 1 | V19: 1 | W19: 1 | X19: 0
A20: 1940 | B20: 1940 | C20: =INDEX(TextData!B:B,MATCH(B20,TextData!A:A)) -> ソードアダプト | D20: 4 | E20: =INDEX(Define!X:X,MATCH(D20,Define!W:W)) -> 精神 | F20: 3005 | G20: =INDEX([1]Animations!B:B,MATCH(F20,[1]Animations!A:A)) -> Genfulew_Effect/B&S_MinMax_AttackUp | H20: 1 | I20: =INDEX(Define!B:B,MATCH(H20,Define!A:A)) -> 単体 | J20: 0 | K20: 3 | L20: 20 | M20: 1 | N20: =INDEX(Define!E:E,MATCH(M20,Define!D:D)) -> 炎 | O20: 1 | P20: =INDEX(Define!H:H,MATCH(O20,Define!G:G)) -> 魔法 | Q20: 4 | R20: =INDEX(Define!K:K,MATCH(Q20,Define!J:J)) -> 自身 | S20: 4 | T20: =INDEX(Define!N:N,MATCH(S20,Define!M:M)) -> 自身 | U20: 1 | V20: 1 | W20: 1 | X20: 0
A21: 2010 | B21: 2010 | C21: =INDEX(TextData!B:B,MATCH(B21,TextData!A:A)) -> ディスチャージ | D21: 1 | E21: =INDEX(Define!X:X,MATCH(D21,Define!W:W)) -> 元素 | F21: 201 | G21: =INDEX([1]Animations!B:B,MATCH(F21,[1]Animations!A:A)) -> MakerEffect/ThunderOne1 | H21: 1 | I21: =INDEX(Define!B:B,MATCH(H21,Define!A:A)) -> 単体 | J21: 0 | K21: 0 | L21: 10 | M21: 2 | N21: =INDEX(Define!E:E,MATCH(M21,Define!D:D)) -> 雷 | O21: 1 | P21: =INDEX(Define!H:H,MATCH(O21,Define!G:G)) -> 魔法 | Q21: 1 | R21: =INDEX(Define!K:K,MATCH(Q21,Define!J:J)) -> 相手 | S21: 1 | T21: =INDEX(Define!N:N,MATCH(S21,Define!M:M)) -> 単体 | U21: 1 | V21: 1 | W21: 1 | X21: 0
... A70: 5940 | B70: 5940 | C70: =INDEX(TextData!B:B,MATCH(B70,TextData!A:A)) -> アビサルデスペア | D70: 5 | E70: =INDEX(Define!X:X,MATCH(D70,Define!W:W)) -> 超次元 | F70: 501 | G70: =INDEX([1]Animations!B:B,MATCH(F70,[1]Animations!A:A)) -> MakerEffect/DarknessOne1 | H70: 1 | I70: =INDEX(Define!B:B,MATCH(H70,Define!A:A)) -> 単体 | J70: 0 | K70: 3 | L70: 20 | M70: 5 | N70: =INDEX(Define!E:E,MATCH(M70,Define!D:D)) -> 闇 | O70: 1 | P70: =INDEX(Define!H:H,MATCH(O70,Define!G:G)) -> 魔法 | Q70: 1 | R70: =INDEX(Define!K:K,MATCH(Q70,Define!J:J)) -> 相手 | S70: 1 | T70: =INDEX(Define!N:N,MATCH(S70,Define!M:M)) -> 単体 | U70: 1 | V70: 1 | W70: 1 | X70: 0
A71: 6010 | B71: 6010 | C71: =INDEX(TextData!B:B,MATCH(B71,TextData!A:A)) -> 待機 | D71: 0 | E71: =INDEX(Define!X:X,MATCH(D71,Define!W:W)) -> なし | F71: 0 | H71: 1 | I71: =INDEX(Define!B:B,MATCH(H71,Define!A:A)) -> 単体 | J71: 0 | K71: 0 | L71: 0 | M71: 0 | N71: =INDEX(Define!E:E,MATCH(M71,Define!D:D)) -> なし | O71: 1 | P71: =INDEX(Define!H:H,MATCH(O71,Define!G:G)) -> 魔法 | Q71: 4 | R71: =INDEX(Define!K:K,MATCH(Q71,Define!J:J)) -> 自身 | S71: 4 | T71: =INDEX(Define!N:N,MATCH(S71,Define!M:M)) -> 自身 | U71: 1 | V71: 1 | W71: 1 | X71: 0
A72: 6020 | B72: 6020 | C72: =INDEX(TextData!B:B,MATCH(B72,TextData!A:A)) -> 交代 | D72: 0 | E72: =INDEX(Define!X:X,MATCH(D72,Define!W:W)) -> なし | F72: 0 | H72: 1 | I72: =INDEX(Define!B:B,MATCH(H72,Define!A:A)) -> 単体 | J72: 0 | K72: 0 | L72: 0 | M72: 0 | N72: =INDEX(Define!E:E,MATCH(M72,Define!D:D)) -> なし | O72: 1 | P72: =INDEX(Define!H:H,MATCH(O72,Define!G:G)) -> 魔法 | Q72: 2 | R72: =INDEX(Define!K:K,MATCH(Q72,Define!J:J)) -> 味方 | S72: 41 | T72: =INDEX(Define!N:N,MATCH(S72,Define!M:M)) -> 交代専用 | U72: 2 | V72: 1 | W72: 2 | X72: 0
A73: 10010 | B73: 10010 | C73: =INDEX(TextData!B:B,MATCH(B73,TextData!A:A)) -> アンデッド | D73: 6 | E73: =INDEX(Define!X:X,MATCH(D73,Define!W:W)) -> 自己強化 | F73: 51 | G73: =INDEX([1]Animations!B:B,MATCH(F73,[1]Animations!A:A)) -> NA_Effekseer/NA_aura_001 | H73: 1 | I73: =INDEX(Define!B:B,MATCH(H73,Define!A:A)) -> 単体 | J73: 0 | K73: 0 | L73: 0 | M73: 0 | N73: =INDEX(Define!E:E,MATCH(M73,Define!D:D)) -> なし | O73: 2 | P73: =INDEX(Define!H:H,MATCH(O73,Define!G:G)) -> パッシブ | Q73: 4 | R73: =INDEX(Define!K:K,MATCH(Q73,Define!J:J)) -> 自身 | S73: 4 | T73: =INDEX(Define!N:N,MATCH(S73,Define!M:M)) -> 自身 | U73: 1 | V73: 1 | W73: 1 | X73: 0
A74: 10020 | B74: 10020 | C74: =INDEX(TextData!B:B,MATCH(B74,TextData!A:A)) -> エアリアル | D74: 6 | E74: =INDEX(Define!X:X,MATCH(D74,Define!W:W)) -> 自己強化 | F74: 51 | G74: =INDEX([1]Animations!B:B,MATCH(F74,[1]Animations!A:A)) -> NA_Effekseer/NA_aura_001 | H74: 1 | I74: =INDEX(Define!B:B,MATCH(H74,Define!A:A)) -> 単体 | J74: 0 | K74: 0 | L74: 0 | M74: 0 | N74: =INDEX(Define!E:E,MATCH(M74,Define!D:D)) -> なし | O74: 2 | P74: =INDEX(Define!H:H,MATCH(O74,Define!G:G)) -> パッシブ | Q74: 4 | R74: =INDEX(Define!K:K,MATCH(Q74,Define!J:J)) -> 自身 | S74: 4 | T74: =INDEX(Define!N:N,MATCH(S74,Define!M:M)) -> 自身 | U74: 1 | V74: 1 | W74: 1 | X74: 0
A75: 10030 | B75: 10030 | C75: =INDEX(TextData!B:B,MATCH(B75,TextData!A:A)) -> 悪魔 | D75: 6 | E75: =INDEX(Define!X:X,MATCH(D75,Define!W:W)) -> 自己強化 | F75: 51 | G75: =INDEX([1]Animations!B:B,MATCH(F75,[1]Animations!A:A)) -> NA_Effekseer/NA_aura_001 | H75: 1 | I75: =INDEX(Define!B:B,MATCH(H75,Define!A:A)) -> 単体 | J75: 0 | K75: 0 | L75: 0 | M75: 0 | N75: =INDEX(Define!E:E,MATCH(M75,Define!D:D)) -> なし | O75: 2 | P75: =INDEX(Define!H:H,MATCH(O75,Define!G:G)) -> パッシブ | Q75: 4 | R75: =INDEX(Define!K:K,MATCH(Q75,Define!J:J)) -> 自身 | S75: 4 | T75: =INDEX(Define!N:N,MATCH(S75,Define!M:M)) -> 自身 | U75: 1 | V75: 1 | W75: 1 | X75: 0
A76: 10040 | B76: 10040 | C76: =INDEX(TextData!B:B,MATCH(B76,TextData!A:A)) -> クリーチャー | D76: 6 | E76: =INDEX(Define!X:X,MATCH(D76,Define!W:W)) -> 自己強化 | F76: 51 | G76: =INDEX([1]Animations!B:B,MATCH(F76,[1]Animations!A:A)) -> NA_Effekseer/NA_aura_001 | H76: 1 | I76: =INDEX(Define!B:B,MATCH(H76,Define!A:A)) -> 単体 | J76: 0 | K76: 0 | L76: 0 | M76: 0 | N76: =INDEX(Define!E:E,MATCH(M76,Define!D:D)) -> なし | O76: 2 | P76: =INDEX(Define!H:H,MATCH(O76,Define!G:G)) -> パッシブ | Q76: 4 | R76: =INDEX(Define!K:K,MATCH(Q76,Define!J:J)) -> 自身 | S76: 4 | T76: =INDEX(Define!N:N,MATCH(S76,Define!M:M)) -> 自身 | U76: 1 | V76: 1 | W76: 1 | X76: 0
A77: 10050 | B77: 10050 | C77: =INDEX(TextData!B:B,MATCH(B77,TextData!A:A)) -> 野生の記憶 | D77: 6 | E77: =INDEX(Define!X:X,MATCH(D77,Define!W:W)) -> 自己強化 | F77: 51 | G77: =INDEX([1]Animations!B:B,MATCH(F77,[1]Animations!A:A)) -> NA_Effekseer/NA_aura_001 | H77: 1 | I77: =INDEX(Define!B:B,MATCH(H77,Define!A:A)) -> 単体 | J77: 0 | K77: 0 | L77: 0 | M77: 0 | N77: =INDEX(Define!E:E,MATCH(M77,Define!D:D)) -> なし | O77: 2 | P77: =INDEX(Define!H:H,MATCH(O77,Define!G:G)) -> パッシブ | Q77: 4 | R77: =INDEX(Define!K:K,MATCH(Q77,Define!J:J)) -> 自身 | S77: 4 | T77: =INDEX(Define!N:N,MATCH(S77,Define!M:M)) -> 自身 | U77: 1 | V77: 1 | W77: 1 | X77: 0
A78: 10060 | B78: 10060 | C78: =INDEX(TextData!B:B,MATCH(B78,TextData!A:A)) -> 変異生物 | D78: 6 | E78: =INDEX(Define!X:X,MATCH(D78,Define!W:W)) -> 自己強化 | F78: 51 | G78: =INDEX([1]Animations!B:B,MATCH(F78,[1]Animations!A:A)) -> NA_Effekseer/NA_aura_001 | H78: 1 | I78: =INDEX(Define!B:B,MATCH(H78,Define!A:A)) -> 単体 | J78: 0 | K78: 0 | L78: 0 | M78: 0 | N78: =INDEX(Define!E:E,MATCH(M78,Define!D:D)) -> なし | O78: 2 | P78: =INDEX(Define!H:H,MATCH(O78,Define!G:G)) -> パッシブ | Q78: 4 | R78: =INDEX(Define!K:K,MATCH(Q78,Define!J:J)) -> 自身 | S78: 4 | T78: =INDEX(Define!N:N,MATCH(S78,Define!M:M)) -> 自身 | U78: 1 | V78: 1 | W78: 1 | X78: 0
A79: 10110 | B79: 10120 | C79: =INDEX(TextData!B:B,MATCH(B79,TextData!A:A)) -> 先天属性・雷 | D79: 6 | E79: =INDEX(Define!X:X,MATCH(D79,Define!W:W)) -> 自己強化 | F79: 0 | H79: 1 | I79: =INDEX(Define!B:B,MATCH(H79,Define!A:A)) -> 単体 | J79: 0 | K79: 0 | L79: 10 | M79: 2 | N79: =INDEX(Define!E:E,MATCH(M79,Define!D:D)) -> 雷 | O79: 8 | P79: =INDEX(Define!H:H,MATCH(O79,Define!G:G)) -> カインド | Q79: 4 | R79: =INDEX(Define!K:K,MATCH(Q79,Define!J:J)) -> 自身 | S79: 4 | T79: =INDEX(Define!N:N,MATCH(S79,Define!M:M)) -> 自身 | U79: 1 | V79: 1 | W79: 1 | X79: 0
A80: 10120 | B80: 10130 | C80: =INDEX(TextData!B:B,MATCH(B80,TextData!A:A)) -> 先天属性・氷 | D80: 6 | E80: =INDEX(Define!X:X,MATCH(D80,Define!W:W)) -> 自己強化 | F80: 0 | H80: 1 | I80: =INDEX(Define!B:B,MATCH(H80,Define!A:A)) -> 単体 | J80: 0 | K80: 0 | L80: 10 | M80: 3 | N80: =INDEX(Define!E:E,MATCH(M80,Define!D:D)) -> 氷 | O80: 8 | P80: =INDEX(Define!H:H,MATCH(O80,Define!G:G)) -> カインド | Q80: 4 | R80: =INDEX(Define!K:K,MATCH(Q80,Define!J:J)) -> 自身 | S80: 4 | T80: =INDEX(Define!N:N,MATCH(S80,Define!M:M)) -> 自身 | U80: 1 | V80: 1 | W80: 1 | X80: 0
A81: 10130 | B81: 10110 | C81: =INDEX(TextData!B:B,MATCH(B81,TextData!A:A)) -> 先天属性・炎 | D81: 6 | E81: =INDEX(Define!X:X,MATCH(D81,Define!W:W)) -> 自己強化 | F81: 0 | H81: 1 | I81: =INDEX(Define!B:B,MATCH(H81,Define!A:A)) -> 単体 | J81: 0 | K81: 0 | L81: 10 | M81: 1 | N81: =INDEX(Define!E:E,MATCH(M81,Define!D:D)) -> 炎 | O81: 8 | P81: =INDEX(Define!H:H,MATCH(O81,Define!G:G)) -> カインド | Q81: 4 | R81: =INDEX(Define!K:K,MATCH(Q81,Define!J:J)) -> 自身 | S81: 4 | T81: =INDEX(Define!N:N,MATCH(S81,Define!M:M)) -> 自身 | U81: 1 | V81: 1 | W81: 1 | X81: 0
A82: 10140 | B82: 10150 | C82: =INDEX(TextData!B:B,MATCH(B82,TextData!A:A)) -> 先天属性・闇 | D82: 6 | E82: =INDEX(Define!X:X,MATCH(D82,Define!W:W)) -> 自己強化 | F82: 0 | H82: 1 | I82: =INDEX(Define!B:B,MATCH(H82,Define!A:A)) -> 単体 | J82: 0 | K82: 0 | L82: 10 | M82: 5 | N82: =INDEX(Define!E:E,MATCH(M82,Define!D:D)) -> 闇 | O82: 8 | P82: =INDEX(Define!H:H,MATCH(O82,Define!G:G)) -> カインド | Q82: 4 | R82: =INDEX(Define!K:K,MATCH(Q82,Define!J:J)) -> 自身 | S82: 4 | T82: =INDEX(Define!N:N,MATCH(S82,Define!M:M)) -> 自身 | U82: 1 | V82: 1 | W82: 1 | X82: 0
A83: 10150 | B83: 10140 | C83: =INDEX(TextData!B:B,MATCH(B83,TextData!A:A)) -> 先天属性・光 | D83: 6 | E83: =INDEX(Define!X:X,MATCH(D83,Define!W:W)) -> 自己強化 | F83: 0 | H83: 1 | I83: =INDEX(Define!B:B,MATCH(H83,Define!A:A)) -> 単体 | J83: 0 | K83: 0 | L83: 10 | M83: 4 | N83: =INDEX(Define!E:E,MATCH(M83,Define!D:D)) -> 光 | O83: 8 | P83: =INDEX(Define!H:H,MATCH(O83,Define!G:G)) -> カインド | Q83: 4 | R83: =INDEX(Define!K:K,MATCH(Q83,Define!J:J)) -> 自身 | S83: 4 | T83: =INDEX(Define!N:N,MATCH(S83,Define!M:M)) -> 自身 | U83: 1 | V83: 1 | W83: 1 | X83: 0
A84: 10210 | B84: 10210 | C84: =INDEX(TextData!B:B,MATCH(B84,TextData!A:A)) -> 装備スロット数+1 | D84: 6 | E84: =INDEX(Define!X:X,MATCH(D84,Define!W:W)) -> 自己強化 | F84: 0 | H84: 1 | I84: =INDEX(Define!B:B,MATCH(H84,Define!A:A)) -> 単体 | J84: 0 | K84: 0 | L84: 0 | M84: 0 | N84: =INDEX(Define!E:E,MATCH(M84,Define!D:D)) -> なし | O84: 8 | P84: =INDEX(Define!H:H,MATCH(O84,Define!G:G)) -> カインド | Q84: 4 | R84: =INDEX(Define!K:K,MATCH(Q84,Define!J:J)) -> 自身 | S84: 4 | T84: =INDEX(Define!N:N,MATCH(S84,Define!M:M)) -> 自身 | U84: 1 | V84: 1 | W84: 1 | X84: 0
A85: 11010 | B85: 11010 | C85: =INDEX(TextData!B:B,MATCH(B85,TextData!A:A)) -> フレイムセイバー | D85: 6 | E85: =INDEX(Define!X:X,MATCH(D85,Define!W:W)) -> 自己強化 | F85: 1109 | G85: =INDEX([1]Animations!B:B,MATCH(F85,[1]Animations!A:A)) -> MakerEffect/Flash | H85: 1 | I85: =INDEX(Define!B:B,MATCH(H85,Define!A:A)) -> 単体 | J85: 0 | K85: 3 | L85: 20 | M85: 1 | N85: =INDEX(Define!E:E,MATCH(M85,Define!D:D)) -> 炎 | O85: 2 | P85: =INDEX(Define!H:H,MATCH(O85,Define!G:G)) -> パッシブ | Q85: 7 | R85: =INDEX(Define!K:K,MATCH(Q85,Define!J:J)) -> 追撃 | S85: 1 | T85: =INDEX(Define!N:N,MATCH(S85,Define!M:M)) -> 単体 | U85: 1 | V85: 1 | W85: 1 | X85: 0
A86: 11020 | B86: 11020 | C86: =INDEX(TextData!B:B,MATCH(B86,TextData!A:A)) -> イーグルアイ | D86: 6 | E86: =INDEX(Define!X:X,MATCH(D86,Define!W:W)) -> 自己強化 | F86: 3005 | G86: =INDEX([1]Animations!B:B,MATCH(F86,[1]Animations!A:A)) -> Genfulew_Effect/B&S_MinMax_AttackUp | H86: 1 | I86: =INDEX(Define!B:B,MATCH(H86,Define!A:A)) -> 単体 | J86: 0 | K86: 3 | L86: 20 | M86: 1 | N86: =INDEX(Define!E:E,MATCH(M86,Define!D:D)) -> 炎 | O86: 2 | P86: =INDEX(Define!H:H,MATCH(O86,Define!G:G)) -> パッシブ | Q86: 4 | R86: =INDEX(Define!K:K,MATCH(Q86,Define!J:J)) -> 自身 | S86: 4 | T86: =INDEX(Define!N:N,MATCH(S86,Define!M:M)) -> 自身 | U86: 1 | V86: 1 | W86: 1 | X86: 0
A87: 11030 | B87: 11030 | C87: =INDEX(TextData!B:B,MATCH(B87,TextData!A:A)) -> ウォークライ | D87: 6 | E87: =INDEX(Define!X:X,MATCH(D87,Define!W:W)) -> 自己強化 | F87: 3005 | G87: =INDEX([1]Animations!B:B,MATCH(F87,[1]Animations!A:A)) -> Genfulew_Effect/B&S_MinMax_AttackUp | H87: 1 | I87: =INDEX(Define!B:B,MATCH(H87,Define!A:A)) -> 単体 | J87: 0 | K87: 0 | L87: 20 | M87: 1 | N87: =INDEX(Define!E:E,MATCH(M87,Define!D:D)) -> 炎 | O87: 2 | P87: =INDEX(Define!H:H,MATCH(O87,Define!G:G)) -> パッシブ | Q87: 4 | R87: =INDEX(Define!K:K,MATCH(Q87,Define!J:J)) -> 自身 | S87: 4 | T87: =INDEX(Define!N:N,MATCH(S87,Define!M:M)) -> 自身 | U87: 1 | V87: 1 | W87: 1 | X87: 0
A88: 11040 | B88: 11040 | C88: =INDEX(TextData!B:B,MATCH(B88,TextData!A:A)) -> ウルフソウル | D88: 6 | E88: =INDEX(Define!X:X,MATCH(D88,Define!W:W)) -> 自己強化 | F88: 3005 | G88: =INDEX([1]Animations!B:B,MATCH(F88,[1]Animations!A:A)) -> Genfulew_Effect/B&S_MinMax_AttackUp | H88: 1 | I88: =INDEX(Define!B:B,MATCH(H88,Define!A:A)) -> 単体 | J88: 0 | K88: 0 | L88: 20 | M88: 1 | N88: =INDEX(Define!E:E,MATCH(M88,Define!D:D)) -> 炎 | O88: 2 | P88: =INDEX(Define!H:H,MATCH(O88,Define!G:G)) -> パッシブ | Q88: 4 | R88: =INDEX(Define!K:K,MATCH(Q88,Define!J:J)) -> 自身 | S88: 4 | T88: =INDEX(Define!N:N,MATCH(S88,Define!M:M)) -> 自身 | U88: 1 | V88: 1 | W88: 1 | X88: 0
...

Sheet Features
A1: SkillId | B1: _ | C1: FeatureType | D1: _ | E1: Param1 | F1: Param2 | G1: Param3 | H1: Rate
A2: 2 | B2: =INDEX(TextData!B:B,MATCH(A2,TextData!A:A)) -> はずす | C2: 1010 | D2: =INDEX(Define!Q:Q,MATCH(C2,Define!P:P)) -> Hpダメージ | E2: 50 | F2: 0 | G2: 0 | H2: 100
A3: 11 | B3: =INDEX(TextData!B:B,MATCH(A3,TextData!A:A)) -> 覚醒 | C3: 3010 | D3: =INDEX(Define!Q:Q,MATCH(C3,Define!P:P)) -> ステート付与 | E3: 1010 | F3: 0 | G3: 10 | H3: 100 | I3: =INDEX([2]TextData!B:B,MATCH(E3,[2]TextData!A:A)) -> 覚醒
A4: 21 | B4: =INDEX(TextData!B:B,MATCH(A4,TextData!A:A)) -> 覚醒解除 | C4: 0 | D4: =INDEX(Define!Q:Q,MATCH(C4,Define!P:P)) -> ない | E4: 0 | F4: 0 | G4: 0 | H4: 100 | I4: =INDEX([2]TextData!B:B,MATCH(E4,[2]TextData!A:A)) -> #N/A
A5: 31 | B5: =INDEX(TextData!B:B,MATCH(A5,TextData!A:A)) -> 拘束制御 | C5: 1050 | D5: =INDEX(Define!Q:Q,MATCH(C5,Define!P:P)) -> 効果無視Hpダメージ | E5: 100 | F5: 0 | G5: 0 | H5: 100
A6: 31 | B6: =INDEX(TextData!B:B,MATCH(A6,TextData!A:A)) -> 拘束制御 | C6: 3020 | D6: =INDEX(Define!Q:Q,MATCH(C6,Define!P:P)) -> ステート解除 | E6: 2020 | F6: 0 | G6: 0 | H6: 100 | I6: =INDEX([2]TextData!B:B,MATCH(E6,[2]TextData!A:A)) -> 暗闇
A7: 32 | B7: =INDEX(TextData!B:B,MATCH(A7,TextData!A:A)) -> 拘束ダメージ解除 | C7: 3020 | D7: =INDEX(Define!Q:Q,MATCH(C7,Define!P:P)) -> ステート解除 | E7: 2021 | F7: 0 | G7: 0 | H7: 100 | I7: =INDEX([2]TextData!B:B,MATCH(E7,[2]TextData!A:A)) -> 暗闇
A8: 33 | B8: =INDEX(TextData!B:B,MATCH(A8,TextData!A:A)) -> 居合 | C8: 1010 | D8: =INDEX(Define!Q:Q,MATCH(C8,Define!P:P)) -> Hpダメージ | E8: 150 | F8: 0 | G8: 0 | H8: 100
A9: 33 | B9: =INDEX(TextData!B:B,MATCH(A9,TextData!A:A)) -> 居合 | C9: 5030 | D9: =INDEX(Define!Q:Q,MATCH(C9,Define!P:P)) -> 再行動する | E9: 0 | F9: 0 | G9: 0 | H9: 100
A10: 41 | B10: =INDEX(TextData!B:B,MATCH(A10,TextData!A:A)) -> 居合 | C10: 40090 | D10: =INDEX(Define!Q:Q,MATCH(C10,Define!P:P)) -> 装備スロット増加 | E10: 0 | F10: 0 | G10: 0 | H10: 100
A11: 1010 | B11: =INDEX(TextData!B:B,MATCH(A11,TextData!A:A)) -> ファイアボール | C11: 1010 | D11: =INDEX(Define!Q:Q,MATCH(C11,Define!P:P)) -> Hpダメージ | E11: 100 | F11: 0 | G11: 0 | H11: 100
A12: 1020 | B12: =INDEX(TextData!B:B,MATCH(A12,TextData!A:A)) -> フレイムクラッシュ | C12: 1010 | D12: =INDEX(Define!Q:Q,MATCH(C12,Define!P:P)) -> Hpダメージ | E12: 100 | F12: 0 | G12: 0 | H12: 100
A13: 1020 | B13: =INDEX(TextData!B:B,MATCH(A13,TextData!A:A)) -> フレイムクラッシュ | C13: 3010 | D13: =INDEX(Define!Q:Q,MATCH(C13,Define!P:P)) -> ステート付与 | E13: 1053 | F13: 2 | G13: 20 | H13: 100
A14: 1030 | B14: =INDEX(TextData!B:B,MATCH(A14,TextData!A:A)) -> ブレイクウォール | C14: 1100 | D14: =INDEX(Define!Q:Q,MATCH(C14,Define!P:P)) -> Hp貫通ダメージ、Param2でKind指定可 | E14: 100 | F14: 2 | G14: 100 | H14: 100
A15: 1040 | B15: =INDEX(TextData!B:B,MATCH(A15,TextData!A:A)) -> フィニッシュスタブ | C15: 1010 | D15: =INDEX(Define!Q:Q,MATCH(C15,Define!P:P)) -> Hpダメージ | E15: 100 | F15: 0 | G15: 0 | H15: 100
A16: 1040 | B16: =INDEX(TextData!B:B,MATCH(A16,TextData!A:A)) -> フィニッシュスタブ | C16: 7020 | D16: =INDEX(Define!Q:Q,MATCH(C16,Define!P:P)) -> 行動後条件付きスキル | E16: 2061 | F16: 0 | G16: 0 | H16: 100
A17: 1040 | B17: =INDEX(TextData!B:B,MATCH(A17,TextData!A:A)) -> フィニッシュスタブ | C17: 3010 | D17: =INDEX(Define!Q:Q,MATCH(C17,Define!P:P)) -> ステート付与 | E17: 1042 | F17: 1 | G17: 30 | H17: 100
A18: 1050 | B18: =INDEX(TextData!B:B,MATCH(A18,TextData!A:A)) -> フレイムレイン | C18: 1010 | D18: =INDEX(Define!Q:Q,MATCH(C18,Define!P:P)) -> Hpダメージ | E18: 40 | F18: 0 | G18: 0 | H18: 100
A19: 1070 | B19: =INDEX(TextData!B:B,MATCH(A19,TextData!A:A)) -> バーニングソウル | C19: 3060 | D19: =INDEX(Define!Q:Q,MATCH(C19,Define!P:P)) -> デバフステート解除 | E19: 0 | F19: 0 | G19: 0 | H19: 100
A20: 1080 | B20: =INDEX(TextData!B:B,MATCH(A20,TextData!A:A)) -> レイジングバウンサー | C20: 3040 | D20: =INDEX(Define!Q:Q,MATCH(C20,Define!P:P)) -> 次の行動まで有効なステート付与 | E20: 1070 | F20: 2 | G20: 30 | H20: 100 | I20: 会心率アップ
A21: 1080 | B21: =INDEX(TextData!B:B,MATCH(A21,TextData!A:A)) -> レイジングバウンサー | C21: 5030 | D21: =INDEX(Define!Q:Q,MATCH(C21,Define!P:P)) -> 再行動する | E21: 0 | F21: 0 | G21: 0 | H21: 100
A22: 1110 | B22: =INDEX(TextData!B:B,MATCH(A22,TextData!A:A)) -> バーンストーム | C22: 1010 | D22: =INDEX(Define!Q:Q,MATCH(C22,Define!P:P)) -> Hpダメージ | E22: 80 | F22: 0 | G22: 0 | H22: 100
A23: 1110 | B23: =INDEX(TextData!B:B,MATCH(A23,TextData!A:A)) -> バーンストーム | C23: 3010 | D23: =INDEX(Define!Q:Q,MATCH(C23,Define!P:P)) -> ステート付与 | E23: 1053 | F23: 2 | G23: 15 | H23: 100
A24: 1120 | B24: =INDEX(TextData!B:B,MATCH(A24,TextData!A:A)) -> イクスティンクション | C24: 1010 | D24: =INDEX(Define!Q:Q,MATCH(C24,Define!P:P)) -> Hpダメージ | E24: 200 | F24: 0 | G24: 0 | H24: 100
A25: 1930 | B25: =INDEX(TextData!B:B,MATCH(A25,TextData!A:A)) -> ヒートスタンプ | C25: 4020 | D25: =INDEX(Define!Q:Q,MATCH(C25,Define!P:P)) -> Ct回復 | E25: 1 | F25: 0 | G25: 0 | H25: 100
A26: 1940 | B26: =INDEX(TextData!B:B,MATCH(A26,TextData!A:A)) -> ソードアダプト | C26: 3010 | D26: =INDEX(Define!Q:Q,MATCH(C26,Define!P:P)) -> ステート付与 | E26: 2290 | F26: 999 | G26: 10 | H26: 100 | I26: ダメージ威力アップ
A27: 2010 | B27: =INDEX(TextData!B:B,MATCH(A27,TextData!A:A)) -> ディスチャージ | C27: 1010 | D27: =INDEX(Define!Q:Q,MATCH(C27,Define!P:P)) -> Hpダメージ | E27: 100 | F27: 0 | G27: 0 | H27: 100
A28: 2020 | B28: =INDEX(TextData!B:B,MATCH(A28,TextData!A:A)) -> シャープエッジ | C28: 1120 | D28: =INDEX(Define!Q:Q,MATCH(C28,Define!P:P)) -> 会心率ありHpダメージ | E28: 100 | F28: 50 | G28: 0 | H28: 100
A29: 2030 | B29: =INDEX(TextData!B:B,MATCH(A29,TextData!A:A)) -> ロングスラスト | C29: 1010 | D29: =INDEX(Define!Q:Q,MATCH(C29,Define!P:P)) -> Hpダメージ | E29: 100 | F29: 0 | G29: 0 | H29: 100
A30: 2040 | B30: =INDEX(TextData!B:B,MATCH(A30,TextData!A:A)) -> スパイラルソード | C30: 1010 | D30: =INDEX(Define!Q:Q,MATCH(C30,Define!P:P)) -> Hpダメージ | E30: 100 | F30: 0 | G30: 0 | H30: 100
A31: 2040 | B31: =INDEX(TextData!B:B,MATCH(A31,TextData!A:A)) -> スパイラルソード | C31: 3010 | D31: =INDEX(Define!Q:Q,MATCH(C31,Define!P:P)) -> ステート付与 | E31: 1090 | F31: 2 | G31: -20 | H31: 100
A32: 2040 | B32: =INDEX(TextData!B:B,MATCH(A32,TextData!A:A)) -> スパイラルソード | C32: 7010 | D32: =INDEX(Define!Q:Q,MATCH(C32,Define!P:P)) -> 行動後スキル | E32: 2041 | F32: 0 | G32: 0 | H32: 100
A33: 2041 | B33: =INDEX(TextData!B:B,MATCH(A33,TextData!A:A)) -> スパイラルソード | C33: 3010 | D33: =INDEX(Define!Q:Q,MATCH(C33,Define!P:P)) -> ステート付与 | E33: 1090 | F33: 2 | G33: 20 | H33: 100
A34: 2050 | B34: =INDEX(TextData!B:B,MATCH(A34,TextData!A:A)) -> スペルバニシング | C34: 1010 | D34: =INDEX(Define!Q:Q,MATCH(C34,Define!P:P)) -> Hpダメージ | E34: 100 | F34: 0 | G34: 0 | H34: 100
A35: 2050 | B35: =INDEX(TextData!B:B,MATCH(A35,TextData!A:A)) -> スペルバニシング | C35: 3010 | D35: =INDEX(Define!Q:Q,MATCH(C35,Define!P:P)) -> ステート付与 | E35: 2320 | F35: 0 | G35: 0 | H35: 100 | I35: バフ解除
A36: 2060 | B36: =INDEX(TextData!B:B,MATCH(A36,TextData!A:A)) -> アーテニーストライク | C36: 1010 | D36: =INDEX(Define!Q:Q,MATCH(C36,Define!P:P)) -> Hpダメージ | E36: 100 | F36: 0 | G36: 0 | H36: 100
A37: 2060 | B37: =INDEX(TextData!B:B,MATCH(A37,TextData!A:A)) -> アーテニーストライク | C37: 11010 | D37: =INDEX(Define!Q:Q,MATCH(C37,Define!P:P)) -> 命中判定しない | E37: 0 | F37: 0 | G37: 0 | H37: 100
A38: 2060 | B38: =INDEX(TextData!B:B,MATCH(A38,TextData!A:A)) -> アーテニーストライク | C38: 7020 | D38: =INDEX(Define!Q:Q,MATCH(C38,Define!P:P)) -> 行動後条件付きスキル | E38: 2061 | F38: 0 | G38: 0 | H38: 100
A39: 2060 | B39: =INDEX(TextData!B:B,MATCH(A39,TextData!A:A)) -> アーテニーストライク | C39: 5011 | D39: =INDEX(Define!Q:Q,MATCH(C39,Define!P:P)) -> 行動後ApがParam1割 | E39: 50 | F39: 0 | G39: 0 | H39: 100
A40: 2061 | B40: =INDEX(TextData!B:B,MATCH(A40,TextData!A:A)) -> アーテニーストライク | C40: 4020 | D40: =INDEX(Define!Q:Q,MATCH(C40,Define!P:P)) -> Ct回復 | E40: 2 | F40: 0 | G40: 0 | H40: 100
...

Sheet Triggers
A1: SkillId | B1: _ | C1: TriggerType | D1: _ | E1: TriggerTiming | F1: Param1 | G1: Param2 | H1: Param3
A2: 1040 | B2: =INDEX(TextData!B:B,MATCH(A2,TextData!A:A)) -> フィニッシュスタブ | C2: 20140 | D2: =INDEX(Define!V:V,MATCH(C2,Define!U:U)) -> 自身の攻撃で敵を倒す | E2: 61 | F2: 0 | G2: 0 | H2: 0
A3: 2120 | B3: =INDEX(TextData!B:B,MATCH(A3,TextData!A:A)) -> インペイル | C3: 20140 | D3: =INDEX(Define!V:V,MATCH(C3,Define!U:U)) -> 自身の攻撃で敵を倒す | E3: 61 | F3: 0 | G3: 0 | H3: 0
A4: 3021 | B4: =INDEX(TextData!B:B,MATCH(A4,TextData!A:A)) -> シールドバッシュ | C4: 6010 | D4: =INDEX(Define!V:V,MATCH(C4,Define!U:U)) -> StateId状態になっている | E4: 61 | F4: 2030 | G4: 0 | H4: 0
A5: 4030 | B5: =INDEX(TextData!B:B,MATCH(A5,TextData!A:A)) -> ヒーリング | C5: 11011 | D5: =INDEX(Define!V:V,MATCH(C5,Define!U:U)) -> Period中使用回数が〇以下 | E5: 0 | F5: 10 | G5: 0 | H5: 0
A6: 4130 | B6: =INDEX(TextData!B:B,MATCH(A6,TextData!A:A)) -> チャクラ | C6: 11011 | D6: =INDEX(Define!V:V,MATCH(C6,Define!U:U)) -> Period中使用回数が〇以下 | E6: 0 | F6: 3 | G6: 0 | H6: 0
A7: 10010 | B7: =INDEX(TextData!B:B,MATCH(A7,TextData!A:A)) -> アンデッド | C7: 0 | D7: =INDEX(Define!V:V,MATCH(C7,Define!U:U)) -> なし | E7: 1 | F7: 0 | G7: 0 | H7: 0
A8: 10020 | B8: =INDEX(TextData!B:B,MATCH(A8,TextData!A:A)) -> エアリアル | C8: 14410 | D8: =INDEX(Define!V:V,MATCH(C8,Define!U:U)) -> Lvが〇以上 | E8: 1 | F8: 20 | G8: 0 | H8: 0
A9: 10030 | B9: =INDEX(TextData!B:B,MATCH(A9,TextData!A:A)) -> 悪魔 | C9: 0 | D9: =INDEX(Define!V:V,MATCH(C9,Define!U:U)) -> なし | E9: 1 | F9: 0 | G9: 0 | H9: 0
A10: 10040 | B10: =INDEX(TextData!B:B,MATCH(A10,TextData!A:A)) -> クリーチャー | C10: 14410 | D10: =INDEX(Define!V:V,MATCH(C10,Define!U:U)) -> Lvが〇以上 | E10: 1 | F10: 20 | G10: 0 | H10: 0
A11: 10050 | B11: =INDEX(TextData!B:B,MATCH(A11,TextData!A:A)) -> 野生の記憶 | C11: 14410 | D11: =INDEX(Define!V:V,MATCH(C11,Define!U:U)) -> Lvが〇以上 | E11: 1 | F11: 20 | G11: 0 | H11: 0
A12: 10060 | B12: =INDEX(TextData!B:B,MATCH(A12,TextData!A:A)) -> 変異生物 | C12: 14410 | D12: =INDEX(Define!V:V,MATCH(C12,Define!U:U)) -> Lvが〇以上 | E12: 1 | F12: 20 | G12: 0 | H12: 0
A13: 11010 | B13: =INDEX(TextData!B:B,MATCH(A13,TextData!A:A)) -> フレイムセイバー | C13: 10010 | D13: =INDEX(Define!V:V,MATCH(C13,Define!U:U)) -> 攻撃成功時〇%で | E13: 61 | F13: 100 | G13: 0 | H13: 0
... A214: 322040 | B214: =INDEX(TextData!B:B,MATCH(A214,TextData!A:A)) -> 詠唱技術Lv1 | C214: 0 | D214: =INDEX(Define!V:V,MATCH(C214,Define!U:U)) -> なし | E214: 1 | F214: 0 | G214: 0 | H214: 0

Sheet ScopeTriggers
A1: SkillId | B1: _ | C1: TriggerType | D1: _ | E1: TriggerTiming | F1: Param1 | G1: Param2 | H1: Param3
A2: 13102 | B2: =INDEX(TextData!B:B,MATCH(A2,TextData!A:A)) -> アイスセイバー | C2: 6030 | D2: =INDEX(Define!V:V,MATCH(C2,Define!U:U)) -> StateId状態になっている味方 | E2: 2 | F2: 2430 | G2: 0 | H2: 0
A3: 13950 | B3: =INDEX(TextData!B:B,MATCH(A3,TextData!A:A)) -> パッシブジャミング | C3: 18020 | D3: =INDEX(Define!V:V,MATCH(C3,Define!U:U)) -> 自分の敵である | E3: 0 | F3: 0 | G3: 0 | H3: 0
A4: 14060 | B4: =INDEX(TextData!B:B,MATCH(A4,TextData!A:A)) -> パッシブサプライ | C4: 18010 | D4: =INDEX(Define!V:V,MATCH(C4,Define!U:U)) -> 自分の味方である | E4: 0 | F4: 0 | G4: 0 | H4: 0
A5: 100610 | B5: =INDEX(TextData!B:B,MATCH(A5,TextData!A:A)) -> サンフレイム | C5: 7020 | D5: =INDEX(Define!V:V,MATCH(C5,Define!U:U)) -> 神化発動後 | E5: 0 | F5: 0 | G5: 0 | H5: 0
A6: 300210 | B6: =INDEX(TextData!B:B,MATCH(A6,TextData!A:A)) -> エーテルリチャージ | C6: 9030 | D6: =INDEX(Define!V:V,MATCH(C6,Define!U:U)) -> ターン数がparam1 x ターン数 + param2 | E6: 2 | F6: 3 | G6: 0 | H6: 1
A7: 300210 | B7: =INDEX(TextData!B:B,MATCH(A7,TextData!A:A)) -> エーテルリチャージ | C7: 16010 | D7: =INDEX(Define!V:V,MATCH(C7,Define!U:U)) -> 攻撃したのが自身 | E7: 2 | F7: 0 | G7: 0 | H7: 0
A8: 301010 | B8: =INDEX(TextData!B:B,MATCH(A8,TextData!A:A)) -> ディケイドリセット | C8: 9030 | D8: =INDEX(Define!V:V,MATCH(C8,Define!U:U)) -> ターン数がparam1 x ターン数 + param2 | E8: 2 | F8: 0 | G8: 10 | H8: 1
A9: 301010 | B9: =INDEX(TextData!B:B,MATCH(A9,TextData!A:A)) -> ディケイドリセット | C9: 16010 | D9: =INDEX(Define!V:V,MATCH(C9,Define!U:U)) -> 攻撃したのが自身 | E9: 2 | F9: 0 | G9: 0 | H9: 0
A10: 301020 | B10: =INDEX(TextData!B:B,MATCH(A10,TextData!A:A)) -> ウォーリアーブラッド | C10: 20140 | D10: =INDEX(Define!V:V,MATCH(C10,Define!U:U)) -> 自身の攻撃で敵を倒す | E10: 2 | F10: 0 | G10: 0 | H10: 0
A11: 301030 | B11: =INDEX(TextData!B:B,MATCH(A11,TextData!A:A)) -> トライアングルガード | C11: 9030 | D11: =INDEX(Define!V:V,MATCH(C11,Define!U:U)) -> ターン数がparam1 x ターン数 + param2 | E11: 2 | F11: 3 | G11: 0 | H11: 1
A12: 301030 | B12: =INDEX(TextData!B:B,MATCH(A12,TextData!A:A)) -> トライアングルガード | C12: 16010 | D12: =INDEX(Define!V:V,MATCH(C12,Define!U:U)) -> 攻撃したのが自身 | E12: 2 | F12: 0 | G12: 0 | H12: 0
A13: 301040 | B13: =INDEX(TextData!B:B,MATCH(A13,TextData!A:A)) -> セーフティバリア | C13: 9030 | D13: =INDEX(Define!V:V,MATCH(C13,Define!U:U)) -> ターン数がparam1 x ターン数 + param2 | E13: 2 | F13: 0 | G13: 2 | H13: 1
... A19: 320012 | B19: =INDEX(TextData!B:B,MATCH(A19,TextData!A:A)) -> 訓練所Lv3 | C19: 14520 | D19: =INDEX(Define!V:V,MATCH(C19,Define!U:U)) -> Lvが低い味方 | E19: 2 | F19: 3 | G19: 0 | H19: 0

Sheet TextData
A1: Id | B1: Text | C1: Help | F1: EnglishText | G1: EnglishHelp
A2: 0 | B2: - | C2: "" | F2: - | G2: ""
A3: 1 | B3: はずす | C3: "" | F3: Remove | G3: ""
A4: 11 | B4: 覚醒 | C4: 覚醒状態になる /s | F4: Awaken | G4: 覚醒状態になる /s
A5: 21 | B5: 覚醒解除 | C5: \sの覚醒を解除 | F5: Awakening Cancel | G5: \sの覚醒を解除
A6: 31 | B6: 拘束制御 | C6: \sにダメージ | F6: Bind Control | G6: \sにダメージ
A7: 32 | B7: 拘束ダメージ解除 | C7: "" | F7: Bind Damage Removal | G7: ""
A8: 33 | B8: 居合 | C8: \sにダメージ | F8: Ready Position | G8: \sにダメージ
A9: 1010 | B9: ファイアボール | C9: \sにATKx/f[f,0,1]%ダメージ | F9: Fireball | G9: Deal ATKx/f[f,0,1]% damage to \s.
A10: 1020 | B10: フレイムクラッシュ | C10: \sにATKx/f[f,0,1]%ダメージ /f[f,1,2]ターンDEF-/f[f,1,3]% | F10: Flame Crash | G10: Deal ATKx/f[f,0,1]% damage to \s for /f[f,1,2] turns. DEF reduced by /f[f,1,3]%.
A11: 1030 | B11: ブレイクウォール | C11: \sにATKx/f[f,0,1]%ダメージ 氷属性の場合DEFを100%無視する | F11: Break Wall | G11: Deal ATKx/f[f,0,1]% damage to \s. Ignore DEF completely if the target is Ice-type.
A12: 1040 | B12: フィニッシュスタブ | C12: \sにATKx/f[f,0,1]%ダメージ 対象を倒した場合/f[f,2,2]ターンATK+/f[f,2,3]% | F12: Finish Stub | G12: Deal ATKx/f[f,0,1]% damage to \s. ATK increases by /f[f,1,3]. if target is defeated.
A13: 1050 | B13: フレイムレイン | C13: \sにATKx/f[f,0,1]%の5連ダメージ | F13: Flame Rain | G13: Deal ATKx/f[f,0,1]% damage 5 times to \s.
... A48: 4040 | B48: ピアシングランス | C48: \sにATKx/f[f,0,1]%ダメージ \sにダメージ軽減効果無視を付与 | F48: Piercing Lance | G48: Deal ATKx/f[f,0,1]% damage to \s Ignore guard activation for /f[f,1,2] turns.
A49: 4050 | B49: べネディクション | C49: 自身以外のHpを/f[f,0,1]回復 | D49: アクトヒール | F49: Benediction | G49: Restore HP of all allies except self by /f[f,0,1].
A50: 4060 | B50: ホーリーグレイス | C50: \sを蘇生してHpを/f[f,0,1]回復 | F50: Holy Grace | G50: Resurrect \s and restore their HP by /f[f,0,1] points.
A51: 4070 | B51: キュアエール | C51: \sのHpを/f[f,0,1]回復 状態異常を回復 | F51: Cure Ale | G51: Restore \s's HP by /f[f,0,1]. Remove status ailments.
A52: 4080 | B52: ラインバリア | C52: 1回だけ\sが受けるダメージを/f[f,0,3]%カット | F52: Line Barrier | G52: Reduce damage taken by \s by /f[f,0,3]% for one hit.
A53: 4110 | B53: ダブルレーザー | C53: \sにATKx/f[f,0,1]%2連ダメージ | F53: Photon | G53: Deal ATKx/f[f,0,1]% damage to \s.
A54: 4120 | B54: リザイアフォトン | C54: \sにATKx/f[f,0,1]%ダメージ 味方全員に攻撃成功回数x/f[f,1,3]のHp回復 | F54: Resia Photon | G54: Deal ATKx/f[f,0,1]% damage to \s. Restore HP of all allies by attack success count x /f[f,1,3].
A55: 4130 | B55: チャクラ | C55: (制限)出撃中3回まで 自身以外の\sのHpを/f[f,0,1]回復 | F55: Chakra | G55: (Limit: 3 uses per sortie) Restore HP of other ally units by /f[f,0,1] points.
A56: 5010 | B56: ダークプリズン | C56: \sにATKx/f[f,0,1]%ダメージ | F56: Dark Prison | G56: Deal ATKx/f[f,0,1]% damage to \s.
A57: 5020 | B57: カウントジャグラー | C57: \sにATKx/f[f,0,1]%ダメージ CT+/f[f,1,1] 自身のCT-/f[f,1,1] | F57: Count Juggler | G57: Deal ATKx/f[f,0,1]% damage to \s. Increase CT by /f[f,1,1] for the target and decrease CT by /f[f,1,1] for self.
A58: 5030 | B58: パッシブカース | C58: \sのCT+/f[f,1,1]し行動が少し遅くなる | F58: Passive Curse | G58: Increase \s's CT by /f[f,1,1]. making their actions slightly slower.
A59: 5040 | B59: ディレイショット | C59: \sにATKx/f[f,0,1]%ダメージ \sのSPDを/f[f,1,2]ターン/f[f,1,3]%ダウン | F59: Delay Shot | G59: Deal ATKx/f[f,0,1]% damage to \s. Decrease \s`s SPD by /f[f,0,3]% for /f[f,0,2] turns.
A60: 5050 | B60: ディプラヴィティ | C60: \sにATKx/f[f,0,1]%ダメージ CT+/f[f,1,1] | D60: ランペイジ,パッシブブレイク | F60: Diplaviti | G60: Deal ATKx/f[f,0,1]% damage to \s. CT+/f[f,1,1]
A61: 5060 | B61: ダークネス | C61: \sに/f[f,0,2]ターン命中率/f[f,0,3]%ダウンを付与 | F61: Darkness | G61: Reduce \s's accuracy by /f[f,0,3]% for /f[f,0,2] turns.
A62: 5080 | B62: ポイズンブロウ | C62: \sにATKx/f[f,0,1]%ダメージ /f[f,1,2]ターン/f[f,1,3]ダメージの毒付与 /s | F62: Poison Breath | G62: Deal ATKx/f[f,0,1]% damage to \s. Apply poison that deals /f[f,1,3] damage over /f[f,1,2] turns. /s
A63: 5110 | B63: ドレインヒール | C63: \sにATKx/f[f,0,1]%ダメージ ダメージの/f[f,0,3]%分Hp回復 | F63: Drain Heal | G63: Deal ATKx/f[f,0,1]% damage to \s. Restore HP by /f[f,0,3]% of the damage dealt.
A64: 5120 | B64: ユーサネイジア | C64: \sにATKx/f[f,0,1]%ダメージ | F64: Ouse Negaisa | G64: Deal ATKx/f[f,0,1]% damage to \s.
A65: 5130 | B65: シェイディークラウド | C65: \sのATKを/f[f,0,3]%ダウン | F65: Shady Cloud | G65: Reduce \s's ATK by /f[f,0,3]%.
A66: 5940 | B66: アビサルデスペア | C66: \sにATKx/f[f,0,1]%ダメージ /f[f,1,2]ターンの不治付与 /s | F66: Abyssal Despair | G66: Deal ATKx/f[f,0,1]% damage to \s. Apply /f[f,1,2] turns of incurable status. /s
A67: 6010 | B67: 待機 | C67: 何もしない | F67: Waiting | G67: Do nothing.
A68: 6020 | B68: 交代 | C68: 仲間と交代する | F68: Shift | G68: Swap positions with an ally unit.
A69: 10010 | B69: アンデッド | C69: (条件)Lv20以上 アンデッド状態になる 行動後自身のHpを/f[f,0,3]%回復する | F69: Undead | G69: (Condition: Level 20 or higher) Become Undead. Restore self's HP by /f[f,0,3]% after action.
A70: 10020 | B70: エアリアル | C70: (条件)Lv10以上 攻撃範囲が延長する /s | F70: Aerial | G70: (Condition: Level 10 or higher) Extend attack range. /s
A71: 10030 | B71: 悪魔 | C71: (条件)Lv10以上 最大AP+/f[f,0,3] | F71: Devil | G71: (Condition: Level 10 or higher) Increase maximum AP by /f[f,0,3].
A72: 10040 | B72: クリーチャー | C72: (条件)Lv10以上 最大Hpが/f[f,0,3]アップ | F72: Creature | G72: (Condition: Level 10 or higher) Max HP increases by /f[f,0,3].
... A94: 11930 | B94: アサルトシフト | C94: (条件)バトル開始時 \sのDEFが/f[f,0,3]ダウンしATKが/f[f,0,3]アップ | F94: Assault Shift | G94: (Condition: At the start of battle) Decrease \s's DEF by /f[f,0,3] and increase ATK by /f[f,0,3].
A95: 11940 | B95: アクティブギフト | C95: (条件)他の味方が攻撃する際に発動 \sのCT-/f[f,0,1] | D95: アクティブギフト | F95: Active Gift | G95: (Condition: When another ally attacks) Decrease \s's CT by /f[f,0,1].
...

Sheet Define
A1: AnimationType | D1: Attribute | G1: SkillType | J1: TargetType | M1: Scope | P1: Feature | S1: State | U1: Trigger | W1: MagicType | Y1: TriggerTiming
A2: 0 | B2: なし | D2: 0 | E2: なし | G2: 0 | H2: なし | J2: 0 | K2: なし | M2: 0 | N2: なし | P2: 0 | Q2: ない | U2: 0 | V2: なし | W2: 0 | X2: なし | Y2: -1 | Z2: なし | AB2: 301 | AC2: Numinous加算
A3: 1 | B3: 単体 | D3: 1 | E3: 炎 | G3: 1 | H3: 魔法 | J3: 1 | K3: 相手 | M3: 1 | N3: 単体 | P3: 1010 | Q3: Hpダメージ | U3: 1010 | V3: 自身のHpが〇%以下 | W3: 1 | X3: 元素 | Y3: 1 | Z3: バトル開始時 | AB3: 302 | AC3: Numinouse消費率
A4: 2 | B4: 列 | D4: 2 | E4: 雷 | G4: 2 | H4: パッシブ | J4: 2 | K4: 味方 | M4: 2 | N4: 列 | P4: 1020 | Q4: Hp吸収ダメージ | U4: 1020 | V4: 自身のHpが〇%以上 | W4: 2 | X4: 光 | Y4: 11 | Z4: Hpが減る | AB4: 303 | AC4: 敵Lv
A5: 3 | B5: 全体 | D5: 3 | E5: 氷 | G5: 3 | H5: 神化 | J5: 3 | K5: 全員 | M5: 3 | N5: 全体 | P5: 1030 | Q5: Hp固定ダメージ | U5: 1030 | V5: Hp%〇以下の味方 | W5: 3 | X5: 理術 | Y5: 21 | Z5: 自身の行動前 | AB5: 304 | AC5: SP加算
D6: 4 | E6: 光 | G6: 4 | H6: 覚醒 | J6: 4 | K6: 自身 | M6: 4 | N6: 自身 | P6: 1040 | Q6: 特定ステートダメージ | U6: 1040 | V6: Hp%〇以上の味方 | W6: 4 | X6: 精神 | Y6: 22 | Z6: 相手の行動前・対象決定前 | AB6: 305 | AC6: 隷従属度
D7: 5 | E7: 闇 | G7: 5 | H7: レリック | J7: 6 | K7: 反撃 | M7: 5 | N7: 最前列のみ | P7: 1050 | Q7: 効果無視Hpダメージ | U7: 1050 | V7: Hp%〇以下の敵 | W7: 5 | X7: 超次元 | Y7: 23 | Z7: 味方の行動前 | AB7: 306 | AC7: アルカナ変更
D8: 6 | E8: 無 | G8: 6 | H8: 強化 | J8: 7 | K8: 追撃 | M8: 6 | N8: 前後貫通 | P8: 1060 | Q8: Hp割合固定ダメージ | U8: 1060 | V8: Hp%〇以上の敵 | W8: 6 | X8: 自己強化 | Y8: 31 | Z8: 割り込み(直前) | AB8: 307 | AC8: ステータスコスト減算
G9: 7 | H9: 装備 | J9: 11 | K9: Triggerの条件を満たす | M9: 11 | N9: 単体・自身を除く | P9: 1070 | Q9: Hpダメージ割合追加ダメージ | U9: 1130 | V9: 最もHpが少ない味方 | W9: 7 | X9: 工作 | Y9: 41 | Z9: かばう専用。割り込みの最優先 | AB9: 308 | AC9: 敵前衛消滅
G10: 8 | H10: カインド | J10: 101 | K10: パーティ | M10: 12 | N10: 列・自身を除く | P10: 1080 | Q10: Hp犠牲ダメージ | U10: 1140 | V10: 最もHpが多い味方 | W10: 10 | X10: 半神 | Y10: 42 | Z10: 相手の行動前・対象決定後 | AB10: 309 | AC10: 撃破SPアップ
G11: 9 | H11: 装備パッシブ | M11: 13 | N11: 全体・自身を除く | P11: 1090 | Q11: 受けたダメージ総計ダメージ | U11: 1150 | V11: 最もHpが少ない敵 | W11: 11 | X11: 覚醒 | Y11: 51 | Z11: 使ったとき | AB11: 310 | AC11: 属性適性増加
G12: 11 | H12: アルカナ使用 | M12: 21 | N12: ランダム | P12: 1100 | Q12: Hp貫通ダメージ、Param2でKind指定可 | U12: 1160 | V12: 最もHpが多い敵 | W12: 99 | X12: その他 | Y12: 61 | Z12: 使った後 | AB12: 311 | AC12: 命令不可
G13: 12 | H13: 転生 | M13: 31 | N13: 単体と両隣 | P13: 1110 | Q13: 残りHp比例ダメージ | U13: 2010 | V13: 味方にHpが〇%以下がいる | Y13: 101 | Z13: バトル終了時 | AB13: 401 | AC13: コマンドLvアップ
M14: 32 | N14: 自分を除いた両隣 | P14: 1120 | Q14: 会心率ありHpダメージ | U14: 3010 | V14: 自身のMpが〇以下 | AB14: 402 | AC14: ステータスアップ
M15: 41 | N15: 交代専用 | P15: 1130 | Q15: Hpダメージ。残りHpParam2以下%でダメージ+Param3 | U15: 3020 | V15: 自身のMpが〇以上 | AB15: 403 | AC15: 魔法入手
P16: 2010 | Q16: Hp回復 | U16: 3030 | V16: Mp〇未満の味方 | AB16: 404 | AC16: 最大HpとMpアップ
P17: 2011 | Q17: 攻撃対象の最大Hpに比例して回復 | U17: 3040 | V17: Mp〇以上の味方 | AB17: 501 | AC17: ターン数アップ
P18: 2020 | Q18: 自身のHpを1にする | U18: 3050 | V18: Mp〇未満の敵 | AB18: 502 | AC18: Lvアップ
P19: 2030 | Q19: 対象のHpを1にする | U19: 3060 | V19: Mp〇以上の敵 | AB19: 503 | AC19: 習得コスト0
P20: 2040 | Q20: Hpを分け与える | U20: 4010 | V20: 戦闘不能が〇以上存在する | AB20: 504 | AC20: ロスト回避
P21: 2110 | Q21: 与ダメージを味方全体に回復 | U21: 4020 | V21: 生存者が〇以上存在する | AB21: 505 | AC21: 素子補充確定ボーナス
P22: 2120 | Q22: 与ダメージを味方全体にMp回復 | U22: 5010 | V22: 自分が前列にいる | AB22: 506 | AC22: コマンドコスト0
P23: 2130 | Q23: 攻撃成功で味方全体に回復 | U23: 5020 | V23: 自分が後列にいる | AB23: 507 | AC23: 属性適正値アップ
P24: 3010 | Q24: ステート付与 | U24: 5030 | V24: 前列の味方を狙う | AB24: 508 | AC24: コマンドLvアップ
P25: 3020 | Q25: ステート解除 | U25: 5040 | V25: 後列の味方を狙う | AB25: 509 | AC25: 魔法入手
P26: 3030 | Q26: Abnormalステート解除 | U26: 5050 | V26: 前列の敵を狙う
P27: 3040 | Q27: 次の行動まで有効なステート付与 | U27: 5060 | V27: 後列の敵を狙う
P28: 3050 | Q28: バフステート解除 | U28: 5070 | V28: 人数が多い列の味方
P29: 3060 | Q29: デバフステート解除 | U29: 5080 | V29: 人数が多い列の敵
P30: 3070 | Q30: ステートの効果を変更 | U30: 5090 | V30: 人数が少ない列の味方
P31: 4010 | Q31: Ctダメージ | U31: 5100 | V31: 人数が少ない列の敵
P32: 4011 | Q32: CTダメージPassiveのみ | U32: 5110 | V32: 〇人以上いる列の味方
P33: 4020 | Q33: Ct回復 | U33: 5120 | V33: 〇人以上いる列の敵
P34: 4030 | Q34: Ct吸収ダメージ | U34: 5130 | V34: 〇番目の味方
P35: 4040 | Q35: 指定魔法のCｔ回復 | U35: 5140 | V35: 〇番目の敵
P36: 4041 | Q36: 1番Ctの高い魔法のCt回復 | U36: 5150 | V36: 後衛がいる
P37: 5010 | Q37: 行動後Ap設定 | U37: 6010 | V37: StateId状態になっている
... P77: 40090 | Q77: 装備スロット増加 | U77: 9120 | V77: 自身を対象にしない
U78: 10010 | V78: 攻撃成功時〇%で
U79: 10020 | V79: 〇%で
...
