Workbook

Sheet States
A1: Id | B1: NameId | C1: _ | D1: IconBack | E1: IconIndex | F1: IconPath | G1: RemovalTiming | H1: _ | I1: OverWrite | J1: EffectPath | K1: EffectPosition | L1: EffectScale | M1: OverLap | N1: Removal | O1: Abnormal | P1: Buff | Q1: DeBuff | R1: HitCheck | S1: RemoveByAttack | T1: RemoveByDeath
A2: 1 | B2: 1 | C2: =INDEX(TextData!B:B,MATCH(B2,TextData!A:A)) -> 戦闘不能 | D2: 0 | E2: 0 | F2: Death | G2: 0 | H2: =INDEX(Define!B:B,MATCH(G2,Define!A:A)) -> なし | I2: 0 | J2: "" | K2: 0 | L2: 1 | M2: 0 | N2: 0 | O2: 0 | P2: 0 | Q2: 0 | R2: 0 | S2: 0 | T2: 0 | U2: =TextData!C2 -> ""
A3: 10 | B3: 10 | C3: =INDEX(TextData!B:B,MATCH(B3,TextData!A:A)) -> 待機 | D3: 0 | E3: 0 | F3: Wingfoot | G3: 0 | H3: =INDEX(Define!B:B,MATCH(G3,Define!A:A)) -> なし | I3: 0 | J3: "" | K3: 0 | L3: 1 | M3: 0 | N3: 0 | O3: 0 | P3: 0 | Q3: 0 | R3: 0 | S3: 0 | T3: 1 | U3: =TextData!B3 -> 待機
A4: 201 | B4: 201 | C4: =INDEX(TextData!B:B,MATCH(B4,TextData!A:A)) -> 炎適正 | D4: 0 | E4: 0 | F4: 1 | G4: 0 | H4: =INDEX(Define!B:B,MATCH(G4,Define!A:A)) -> なし | I4: 1 | J4: "" | K4: 0 | L4: 1 | M4: 0 | N4: 0 | O4: 0 | P4: 0 | Q4: 0 | R4: 0 | S4: 0 | T4: 0 | U4: =TextData!B4 -> 炎適正
A5: 202 | B5: 202 | C5: =INDEX(TextData!B:B,MATCH(B5,TextData!A:A)) -> 雷適性 | D5: 0 | E5: 0 | F5: 1 | G5: 0 | H5: =INDEX(Define!B:B,MATCH(G5,Define!A:A)) -> なし | I5: 1 | J5: "" | K5: 0 | L5: 1 | M5: 0 | N5: 0 | O5: 0 | P5: 0 | Q5: 0 | R5: 0 | S5: 0 | T5: 0 | U5: =TextData!B5 -> 雷適性
A6: 203 | B6: 203 | C6: =INDEX(TextData!B:B,MATCH(B6,TextData!A:A)) -> 氷適性 | D6: 0 | E6: 0 | F6: 1 | G6: 0 | H6: =INDEX(Define!B:B,MATCH(G6,Define!A:A)) -> なし | I6: 1 | J6: "" | K6: 0 | L6: 1 | M6: 0 | N6: 0 | O6: 0 | P6: 0 | Q6: 0 | R6: 0 | S6: 0 | T6: 0 | U6: =TextData!B6 -> 氷適性
A7: 204 | B7: 204 | C7: =INDEX(TextData!B:B,MATCH(B7,TextData!A:A)) -> 光適性 | D7: 0 | E7: 0 | F7: 1 | G7: 0 | H7: =INDEX(Define!B:B,MATCH(G7,Define!A:A)) -> なし | I7: 1 | J7: "" | K7: 0 | L7: 1 | M7: 0 | N7: 0 | O7: 0 | P7: 0 | Q7: 0 | R7: 0 | S7: 0 | T7: 0 | U7: =TextData!B7 -> 光適性
A8: 205 | B8: 205 | C8: =INDEX(TextData!B:B,MATCH(B8,TextData!A:A)) -> 闇適性 | D8: 0 | E8: 0 | F8: 1 | G8: 0 | H8: =INDEX(Define!B:B,MATCH(G8,Define!A:A)) -> なし | I8: 1 | J8: "" | K8: 0 | L8: 1 | M8: 0 | N8: 0 | O8: 0 | P8: 0 | Q8: 0 | R8: 0 | S8: 0 | T8: 0 | U8: =TextData!B8 -> 闇適性
A9: 1010 | B9: 1010 | C9: =INDEX(TextData!B:B,MATCH(B9,TextData!A:A)) -> 覚醒 | D9: 0 | E9: 0 | F9: Butterfly | G9: 0 | H9: =INDEX(Define!B:B,MATCH(G9,Define!A:A)) -> なし | I9: 0 | J9: "" | K9: 0 | L9: 1 | M9: 0 | N9: 0 | O9: 0 | P9: 0 | Q9: 0 | R9: 0 | S9: 0 | T9: 1 | U9: =TextData!B9 -> 覚醒
A10: 1011 | B10: 1011 | C10: =INDEX(TextData!B:B,MATCH(B10,TextData!A:A)) -> 全ステータスアップ | D10: 0 | E10: 0 | F10: Aura | G10: 0 | H10: =INDEX(Define!B:B,MATCH(G10,Define!A:A)) -> なし | I10: 0 | J10: "" | K10: 0 | L10: 1 | M10: 0 | N10: 0 | O10: 0 | P10: 1 | Q10: 0 | R10: 0 | S10: 0 | T10: 1 | U10: =TextData!B10 -> 全ステータスアップ
A11: 1020 | B11: 1020 | C11: =INDEX(TextData!B:B,MATCH(B11,TextData!A:A)) -> 最大Hpアップ | D11: 0 | E11: 11 | F11: HeartPlus | G11: 1 | H11: =INDEX(Define!B:B,MATCH(G11,Define!A:A)) -> ターン数 | I11: 1 | J11: "" | K11: 0 | L11: 1 | M11: 0 | N11: 1 | O11: 0 | P11: 1 | Q11: 0 | R11: 0 | S11: 0 | T11: 1 | U11: =TextData!B11 -> 最大Hpアップ
A12: 1030 | B12: 1030 | C12: =INDEX(TextData!B:B,MATCH(B12,TextData!A:A)) -> 最大Mpアップ | D12: 0 | E12: 12 | F12: MoebiusTrefoil | G12: 1 | H12: =INDEX(Define!B:B,MATCH(G12,Define!A:A)) -> ターン数 | I12: 1 | J12: "" | K12: 0 | L12: 1 | M12: 0 | N12: 1 | O12: 0 | P12: 1 | Q12: 0 | R12: 0 | S12: 0 | T12: 1 | U12: =TextData!B12 -> 最大Mpアップ
A13: 1040 | B13: 1040 | C13: =INDEX(TextData!B:B,MATCH(B13,TextData!A:A)) -> 攻撃アップ | D13: 0 | E13: 13 | F13: PointySword | G13: 1 | H13: =INDEX(Define!B:B,MATCH(G13,Define!A:A)) -> ターン数 | I13: 1 | J13: "" | K13: 0 | L13: 1 | M13: 0 | N13: 1 | O13: 0 | P13: 1 | Q13: 0 | R13: 0 | S13: 0 | T13: 1 | U13: =TextData!B13 -> 攻撃アップ
A14: 1041 | B14: 1041 | C14: =INDEX(TextData!B:B,MATCH(B14,TextData!A:A)) -> 攻撃ダウン | D14: 0 | E14: 27 | F14: PointySword | G14: 1 | H14: =INDEX(Define!B:B,MATCH(G14,Define!A:A)) -> ターン数 | I14: 1 | J14: "" | K14: 0 | L14: 1 | M14: 0 | N14: 0 | O14: 0 | P14: 0 | Q14: 1 | R14: 0 | S14: 0 | T14: 1 | U14: =TextData!B14 -> 攻撃ダウン
A15: 1042 | B15: 1042 | C15: =INDEX(TextData!B:B,MATCH(B15,TextData!A:A)) -> 攻撃%アップ | D15: 0 | E15: 13 | F15: PointySword | G15: 1 | H15: =INDEX(Define!B:B,MATCH(G15,Define!A:A)) -> ターン数 | I15: 1 | J15: "" | K15: 0 | L15: 1 | M15: 0 | N15: 1 | O15: 0 | P15: 1 | Q15: 0 | R15: 0 | S15: 0 | T15: 1 | U15: =TextData!B15 -> 攻撃%アップ
A16: 1043 | B16: 1043 | C16: =INDEX(TextData!B:B,MATCH(B16,TextData!A:A)) -> 攻撃%ダウン | D16: 0 | E16: 29 | F16: PointySword | G16: 1 | H16: =INDEX(Define!B:B,MATCH(G16,Define!A:A)) -> ターン数 | I16: 1 | J16: "" | K16: 0 | L16: 1 | M16: 0 | N16: 0 | O16: 0 | P16: 0 | Q16: 1 | R16: 0 | S16: 0 | T16: 1 | U16: =TextData!B16 -> 攻撃%ダウン
A17: 1044 | B17: 1044 | C17: =INDEX(TextData!B:B,MATCH(B17,TextData!A:A)) -> 攻撃アップ | D17: 0 | E17: 29 | F17: PointySword | G17: 1 | H17: =INDEX(Define!B:B,MATCH(G17,Define!A:A)) -> ターン数 | I17: 1 | J17: "" | K17: 0 | L17: 1 | M17: 5 | N17: 1 | O17: 0 | P17: 1 | Q17: 0 | R17: 0 | S17: 0 | T17: 1 | U17: =TextData!B17 -> 攻撃アップ
A18: 1050 | B18: 1050 | C18: =INDEX(TextData!B:B,MATCH(B18,TextData!A:A)) -> 防御アップ | D18: 0 | E18: 14 | F18: Shield | G18: 1 | H18: =INDEX(Define!B:B,MATCH(G18,Define!A:A)) -> ターン数 | I18: 1 | J18: "" | K18: 0 | L18: 1 | M18: 0 | N18: 1 | O18: 0 | P18: 1 | Q18: 0 | R18: 0 | S18: 0 | T18: 1 | U18: =TextData!B18 -> 防御アップ
A19: 1051 | B19: 1051 | C19: =INDEX(TextData!B:B,MATCH(B19,TextData!A:A)) -> 防御ダウン | D19: 0 | E19: 30 | F19: Shield | G19: 1 | H19: =INDEX(Define!B:B,MATCH(G19,Define!A:A)) -> ターン数 | I19: 1 | J19: "" | K19: 0 | L19: 1 | M19: 0 | N19: 0 | O19: 0 | P19: 0 | Q19: 1 | R19: 0 | S19: 0 | T19: 1 | U19: =TextData!B19 -> 防御ダウン
A20: 1052 | B20: 1052 | C20: =INDEX(TextData!B:B,MATCH(B20,TextData!A:A)) -> 防御アップ | D20: 0 | E20: 14 | F20: Shield | G20: 1 | H20: =INDEX(Define!B:B,MATCH(G20,Define!A:A)) -> ターン数 | I20: 1 | J20: "" | K20: 0 | L20: 1 | M20: 0 | N20: 1 | O20: 0 | P20: 1 | Q20: 0 | R20: 0 | S20: 0 | T20: 1 | U20: =TextData!B20 -> 防御アップ
... A27: 1080 | B27: 1080 | C27: =INDEX(TextData!B:B,MATCH(B27,TextData!A:A)) -> 命中アップ | D27: 0 | E27: 0 | F27: ArrowScope | G27: 1 | H27: =INDEX(Define!B:B,MATCH(G27,Define!A:A)) -> ターン数 | I27: 1 | J27: "" | K27: 0 | L27: 1 | M27: 0 | N27: 1 | O27: 0 | P27: 1 | Q27: 0 | R27: 0 | S27: 0 | T27: 1 | U27: =TextData!B27 -> 命中アップ
A28: 1081 | B28: 1081 | C28: =INDEX(TextData!B:B,MATCH(B28,TextData!A:A)) -> 命中アップ | D28: 0 | E28: 0 | F28: ArrowScope | G28: 1 | H28: =INDEX(Define!B:B,MATCH(G28,Define!A:A)) -> ターン数 | I28: 1 | J28: "" | K28: 0 | L28: 1 | M28: 5 | N28: 1 | O28: 0 | P28: 1 | Q28: 0 | R28: 0 | S28: 0 | T28: 1 | U28: =TextData!B30 -> 回避アップ
A29: 1082 | B29: 1082 | C29: =INDEX(TextData!B:B,MATCH(B29,TextData!A:A)) -> 命中ダウン | D29: 0 | E29: 0 | F29: ArrowScope | G29: 1 | H29: =INDEX(Define!B:B,MATCH(G29,Define!A:A)) -> ターン数 | I29: 1 | J29: "" | K29: 0 | L29: 1 | M29: 0 | N29: 0 | O29: 0 | P29: 0 | Q29: 1 | R29: 0 | S29: 0 | T29: 1 | U29: =TextData!B31 -> 回避ダウン
A30: 1090 | B30: 1090 | C30: =INDEX(TextData!B:B,MATCH(B30,TextData!A:A)) -> 回避アップ | D30: 0 | E30: 0 | F30: Dodging | G30: 1 | H30: =INDEX(Define!B:B,MATCH(G30,Define!A:A)) -> ターン数 | I30: 1 | J30: "" | K30: 0 | L30: 1 | M30: 0 | N30: 1 | O30: 0 | P30: 1 | Q30: 0 | R30: 0 | S30: 0 | T30: 1 | U30: =TextData!B30 -> 回避アップ
A31: 1091 | B31: 1091 | C31: =INDEX(TextData!B:B,MATCH(B31,TextData!A:A)) -> 回避ダウン | D31: 0 | E31: 0 | F31: Dodging | G31: 1 | H31: =INDEX(Define!B:B,MATCH(G31,Define!A:A)) -> ターン数 | I31: 1 | J31: "" | K31: 0 | L31: 1 | M31: 0 | N31: 1 | O31: 0 | P31: 0 | Q31: 1 | R31: 0 | S31: 0 | T31: 1 | U31: =TextData!B31 -> 回避ダウン
A32: 1092 | B32: 1092 | C32: =INDEX(TextData!B:B,MATCH(B32,TextData!A:A)) -> 回避アップ | D32: 0 | E32: 0 | F32: Dodging | G32: 1 | H32: =INDEX(Define!B:B,MATCH(G32,Define!A:A)) -> ターン数 | I32: 1 | J32: "" | K32: 0 | L32: 1 | M32: 5 | N32: 1 | O32: 0 | P32: 1 | Q32: 0 | R32: 0 | S32: 0 | T32: 1 | U32: =TextData!B32 -> 回避アップ
A33: 1100 | B33: 1100 | C33: =INDEX(TextData!B:B,MATCH(B33,TextData!A:A)) -> ダメージカット | D33: 0 | E33: 96 | F33: BellShield | G33: 4 | H33: =INDEX(Define!B:B,MATCH(G33,Define!A:A)) -> 効果発揮回数 | I33: 1 | J33: "" | K33: 0 | L33: 1 | M33: 0 | N33: 1 | O33: 0 | P33: 1 | Q33: 0 | R33: 0 | S33: 0 | T33: 1 | U33: =TextData!B33 -> ダメージカット
A34: 1101 | B34: 1101 | C34: =INDEX(TextData!B:B,MATCH(B34,TextData!A:A)) -> ダメージカット | D34: 0 | E34: 96 | F34: BellShield | G34: 4 | H34: =INDEX(Define!B:B,MATCH(G34,Define!A:A)) -> 効果発揮回数 | I34: 1 | J34: "" | K34: 0 | L34: 1 | M34: 0 | N34: 1 | O34: 0 | P34: 1 | Q34: 0 | R34: 0 | S34: 0 | T34: 1 | U34: =TextData!B34 -> ダメージカット
A35: 1210 | B35: 1210 | C35: =INDEX(TextData!B:B,MATCH(B35,TextData!A:A)) -> 火傷耐性 | D35: 2 | E35: 43 | F35: Foam | G35: 1 | H35: =INDEX(Define!B:B,MATCH(G35,Define!A:A)) -> ターン数 | I35: 1 | J35: "" | K35: 0 | L35: 1 | M35: 0 | N35: 1 | O35: 0 | P35: 1 | Q35: 0 | R35: 0 | S35: 0 | T35: 1 | U35: =TextData!B35 -> 火傷耐性
A36: 1220 | B36: 1220 | C36: =INDEX(TextData!B:B,MATCH(B36,TextData!A:A)) -> 凍結耐性 | D36: 2 | E36: 96 | F36: Foam | G36: 1 | H36: =INDEX(Define!B:B,MATCH(G36,Define!A:A)) -> ターン数 | I36: 1 | J36: "" | K36: 0 | L36: 1 | M36: 0 | N36: 1 | O36: 0 | P36: 1 | Q36: 0 | R36: 0 | S36: 0 | T36: 1 | U36: =TextData!B36 -> 凍結耐性
A37: 1310 | B37: 1310 | C37: =INDEX(TextData!B:B,MATCH(B37,TextData!A:A)) -> 炎耐性 | D37: 1 | E37: 43 | F37: Foam | G37: 1 | H37: =INDEX(Define!B:B,MATCH(G37,Define!A:A)) -> ターン数 | I37: 1 | J37: "" | K37: 0 | L37: 1 | M37: 0 | N37: 1 | O37: 0 | P37: 1 | Q37: 0 | R37: 0 | S37: 0 | T37: 1 | U37: =TextData!B37 -> 炎耐性
A38: 1320 | B38: 1320 | C38: =INDEX(TextData!B:B,MATCH(B38,TextData!A:A)) -> 雷耐性 | D38: 10 | E38: 45 | F38: Foam | G38: 1 | H38: =INDEX(Define!B:B,MATCH(G38,Define!A:A)) -> ターン数 | I38: 1 | J38: "" | K38: 0 | L38: 1 | M38: 0 | N38: 1 | O38: 0 | P38: 1 | Q38: 0 | R38: 0 | S38: 0 | T38: 1 | U38: =TextData!B38 -> 雷耐性
A39: 1330 | B39: 1330 | C39: =INDEX(TextData!B:B,MATCH(B39,TextData!A:A)) -> 氷耐性 | D39: 18 | E39: 44 | F39: Foam | G39: 1 | H39: =INDEX(Define!B:B,MATCH(G39,Define!A:A)) -> ターン数 | I39: 1 | J39: "" | K39: 0 | L39: 1 | M39: 0 | N39: 1 | O39: 0 | P39: 1 | Q39: 0 | R39: 0 | S39: 0 | T39: 1 | U39: =TextData!B39 -> 氷耐性
A40: 1340 | B40: 1340 | C40: =INDEX(TextData!B:B,MATCH(B40,TextData!A:A)) -> 光耐性 | D40: 13 | E40: 49 | F40: Foam | G40: 1 | H40: =INDEX(Define!B:B,MATCH(G40,Define!A:A)) -> ターン数 | I40: 1 | J40: "" | K40: 0 | L40: 1 | M40: 0 | N40: 1 | O40: 0 | P40: 1 | Q40: 0 | R40: 0 | S40: 0 | T40: 1 | U40: =TextData!B40 -> 光耐性
A41: 1350 | B41: 1350 | C41: =INDEX(TextData!B:B,MATCH(B41,TextData!A:A)) -> 闇耐性 | D41: 14 | E41: 50 | F41: Foam | G41: 1 | H41: =INDEX(Define!B:B,MATCH(G41,Define!A:A)) -> ターン数 | I41: 1 | J41: "" | K41: 0 | L41: 1 | M41: 0 | N41: 1 | O41: 0 | P41: 1 | Q41: 0 | R41: 0 | S41: 0 | T41: 1 | U41: =TextData!B41 -> 闇耐性
A42: 2010 | B42: 2010 | C42: =INDEX(TextData!B:B,MATCH(B42,TextData!A:A)) -> 毒 | D42: 26 | E42: 1 | F42: Foam | G42: 1 | H42: =INDEX(Define!B:B,MATCH(G42,Define!A:A)) -> ターン数 | I42: 1 | J42: MAGICALxSPIRAL/Salamander7 | K42: 1 | L42: 1 | M42: 0 | N42: 0 | O42: 1 | P42: 0 | Q42: 1 | R42: 1 | S42: 0 | T42: 1 | U42: =TextData!B42 -> 毒
A43: 2011 | B43: 2010 | C43: 毒 | D43: 26 | E43: 1 | F43: Foam | G43: 1 | H43: =INDEX(Define!B:B,MATCH(G43,Define!A:A)) -> ターン数 | I43: 1 | J43: MAGICALxSPIRAL/Salamander7 | K43: 1 | L43: 1 | M43: 0 | N43: 0 | O43: 1 | P43: 0 | Q43: 1 | R43: 1 | S43: 0 | T43: 1 | U43: =TextData!B42 -> 毒
A44: 2012 | B44: 2012 | C44: 火傷 | D44: 2 | E44: 43 | F44: Foam | G44: 1 | H44: =INDEX(Define!B:B,MATCH(G44,Define!A:A)) -> ターン数 | I44: 1 | J44: MAGICALxSPIRAL/Salamander7 | K44: 1 | L44: 1 | M44: 0 | N44: 0 | O44: 1 | P44: 0 | Q44: 1 | R44: 1 | S44: 0 | T44: 1 | U44: =TextData!B43 -> 火傷
A45: 2020 | B45: 2020 | C45: =INDEX(TextData!B:B,MATCH(B45,TextData!A:A)) -> 暗闇 | D45: 33 | E45: 2 | F45: ArrowScope | G45: 4 | H45: =INDEX(Define!B:B,MATCH(G45,Define!A:A)) -> 効果発揮回数 | I45: 1 | J45: Blind | K45: 0 | L45: 0.1 | M45: 0 | N45: 0 | O45: 1 | P45: 0 | Q45: 1 | R45: 1 | S45: 0 | T45: 1 | U45: =TextData!B44 -> 暗闇
A46: 2030 | B46: 2030 | C46: =INDEX(TextData!B:B,MATCH(B46,TextData!A:A)) -> カウンタ | D46: 0 | E46: 66 | F46: ShieldReflect | G46: 1 | H46: =INDEX(Define!B:B,MATCH(G46,Define!A:A)) -> ターン数 | I46: 0 | J46: MAGICALxSPIRAL/AquaPoint | K46: 0 | L46: 1 | M46: 0 | N46: 0 | O46: 0 | P46: 0 | Q46: 0 | R46: 0 | S46: 0 | T46: 1 | U46: =TextData!B45 -> カウンタ
...

Sheet TextData
A1: Id | B1: Text | C1: Help | F1: EnglishText | G1: EnglishHelp
A2: 1 | B2: 戦闘不能 | C2: "" | F2: Defeated | G2: ""
A3: 10 | B3: 待機 | C3: "" | F3: Idle | G3: ""
A4: 201 | B4: 炎適正 | C4: 炎魔法の習得に必要な(Nu)コストをダウン | F4: Fire Affinity | G4: Reduce cost to learn Fire Magic by (Nu)
A5: 202 | B5: 雷適性 | C5: 雷魔法の習得に必要な(Nu)コストをダウン | F5: Thunder Affinity | G5: Reduce cost to learn Thunder Magic by (Nu)
A6: 203 | B6: 氷適性 | C6: 氷魔法の習得に必要な(Nu)コストをダウン | F6: Ice Affinity | G6: Reduce cost to learn Ice Magic by (Nu)
A7: 204 | B7: 光適性 | C7: 光魔法の習得に必要な(Nu)コストをダウン | F7: Light Affinity | G7: Reduce cost to learn Light Magic by (Nu)
A8: 205 | B8: 闇適性 | C8: 闇魔法の習得に必要な(Nu)コストをダウン | F8: Dark Affinity | G8: Reduce cost to learn Dark Magic by (Nu)
A9: 1010 | B9: 覚醒 | C9: ATK,DEF,SPDが{0}アップ | F9: Awaken | G9: ATK, DEF, SPD +{0}
A10: 1011 | B10: 全ステータスアップ | C10: 全てのステータスが{0}アップ | F10: All Stats Up | G10: 全てのステータスが{0}Up
A11: 1020 | B11: 最大Hpアップ | C11: MaxHp{0}アップ | F11: Max HP Up | G11: MaxHp{0}Up
A12: 1030 | B12: 最大Mpアップ | C12: MaxMp{0}アップ | F12: Max MP Up | G12: MaxMp{0}Up
A13: 1040 | B13: 攻撃アップ | C13: ATK{0}アップ | F13: Attack Up | G13: ATK{0}Up
... A90: 9999 | B90: テスト用 | C90: "" | F90: テスト用 | G90: ""

Sheet Define
A1: RemovalTiming
A2: 0 | B2: なし
A3: 1 | B3: ターン数
A4: 2 | B4: APカウント
A5: 3 | B5: Chain用
A6: 4 | B6: 効果発揮回数
A7: 5 | B7: 次に行動するまでの間
A8: 6 | B8: ターンの終了
